<?xml version="1.0" encoding="utf-8"?>
<!-- =================================================================================== -->
<!-- |    This document was autogenerated by xacro from arm_stand.urdf.xacro           | -->
<!-- |    EDITING THIS FILE BY HAND IS NOT RECOMMENDED                                 | -->
<!-- =================================================================================== -->
<!-- Revolute-Revolute Manipulator -->
<robot name="arm_stand">
  <!-- Size of square 'camera' box -->
  <material name="black">
    <color rgba="0.0 0.0 0.0 1.0"/>
  </material>
  <material name="blue">
    <color rgba="0.0 0.0 0.8 1.0"/>
  </material>
  <material name="green">
    <color rgba="0.0 1.0 0.0 1.0"/>
  </material>
  <material name="grey">
    <color rgba="0.2 0.2 0.2 1.0"/>
  </material>
  <material name="orange">
    <color rgba="1.0 0.423529411765 0.0392156862745 1.0"/>
  </material>
  <material name="brown">
    <color rgba="0.870588235294 0.811764705882 0.764705882353 1.0"/>
  </material>
  <material name="red">
    <color rgba="0.8 0.0 0.0 1.0"/>
  </material>
  <material name="white">
    <color rgba="1.0 1.0 1.0 1.0"/>
  </material>
  <gazebo reference="camera_joint">
    <preserveFixedJoint>true</preserveFixedJoint>
  </gazebo>
  <!-- Base Link -->
  <gazebo reference="base_link">
    <!--<gravity>false</gravity>-->
    <material>Gazebo/White</material>
  </gazebo>
  <!-- Middle Link -->
  <gazebo reference="mid_link">
    <mu1>0.2</mu1>
    <mu2>0.2</mu2>
    <material>Gazebo/Green</material>
    <turnGravityOff>true</turnGravityOff>
    <!--<gravity>false</gravity>-->
  </gazebo>
  <!-- Top Link -->
  <gazebo reference="top_link">
    <mu1>0.2</mu1>
    <mu2>0.2</mu2>
    <material>Gazebo/Red</material>
    <!--<gravity>false</gravity>-->
    <turnGravityOff>true</turnGravityOff>
  </gazebo>
  <!-- Fore Link -->
  <gazebo reference="fore_link">
    <mu1>0.2</mu1>
    <mu2>0.2</mu2>
    <material>Gazebo/Blue</material>
    <turnGravityOff>true</turnGravityOff>
    <!--<gravity>false</gravity>-->
  </gazebo>
  <gazebo reference="hand_palm_link">
    <!--<gravity>false</gravity>-->
    <turnGravityOff>true</turnGravityOff>
  </gazebo>
  <gazebo reference="hand_tool_link">
    <!--<gravity>false</gravity>-->
    <turnGravityOff>true</turnGravityOff>
  </gazebo>
  <gazebo reference="hand_safety_box">
    <!--<gravity>false</gravity>-->
    <turnGravityOff>true</turnGravityOff>
  </gazebo>
  <!-- ros_control plugin -->
  <gazebo>
    <plugin filename="libgazebo_ros_control.so" name="gazebo_ros_control">
      <robotNamespace>/arm_stand</robotNamespace>
      <robotSimType>gazebo_ros_control/DefaultRobotHWSim</robotSimType>
    </plugin>
  </gazebo>
  <gazebo reference="camera_link">
    <turnGravityOff>true</turnGravityOff>
    <sensor name="camera1" type="camera">
      <update_rate>30.0</update_rate>
      <camera name="camera1">
        <horizontal_fov>1.3962634</horizontal_fov>
        <image>
          <width>800</width>
          <height>800</height>
          <format>R8G8B8</format>
        </image>
        <clip>
          <near>0.02</near>
          <far>300</far>
        </clip>
        <noise>
          <type>gaussian</type>
          <!--Noise is sampled independently per pixel on each frame.
               That pixel's noise value is added to each of its color
               channels, which at that point lie in the range [0,1].-->
          <mean>0.0</mean>
          <stddev>0.007</stddev>
        </noise>
      </camera>
      <plugin filename="libgazebo_ros_camera.so" name="camera_controller">
        <alwaysOn>true</alwaysOn>
        <updateRate>0.0</updateRate>
        <cameraName>camera1</cameraName>
        <imageTopicName>image_raw</imageTopicName>
        <cameraInfoTopicName>camera_info</cameraInfoTopicName>
        <frameName>camera_link</frameName>
        <hackBaseline>0.07</hackBaseline>
        <distortionK1>0.0</distortionK1>
        <distortionK2>0.0</distortionK2>
        <distortionK3>0.0</distortionK3>
        <distortionT1>0.0</distortionT1>
        <distortionT2>0.0</distortionT2>
      </plugin>
    </sensor>
  </gazebo>
  <material name="Hey5DarkGrey">
    <color rgba="0.1 0.1 0.1 1.0"/>
  </material>
  <!--TODO: Check-->
  <!-- Tool Link -->
  <link name="hand_tool_link">
    <inertial>
      <origin rpy="0 0 0" xyz="0 0 0"/>
      <mass value="0.0001"/>
      <inertia ixx="0.00001" ixy="0.0" ixz="0.0" iyy="0.00001" iyz="0.0" izz="0.00001"/>
    </inertial>
  </link>
  <joint name="hand_tool_joint" type="fixed">
    <origin rpy="-1.57 0 0" xyz="0.5 0 0"/>
    <parent link="fore_link"/>
    <child link="hand_tool_link"/>
    <axis xyz="0 0 0"/>
  </joint>
  <joint name="hand_palm_joint" type="fixed">
    <parent link="fore_link"/>
    <child link="hand_palm_link"/>
    <origin rpy="-1.57 0 0" xyz="0.5 0 0"/>
  </joint>
  <link name="hand_palm_link">
    <inertial>
      <origin rpy="0 0 0" xyz="0.0641 -0.0022 0.0021"/>
      <!-- NOTE: Less than total palm mass of 0.598kg because actuator masses are specified separately -->
      <mass value="0.4"/>
      <inertia ixx="0.000305100" ixy="0.000005037" ixz="0.000015302" iyy="0.000811920" iyz="0.000007622" izz="0.000655851"/>
    </inertial>
    <visual>
      <origin rpy="0 0 0" xyz="0 0 0"/>
      <geometry>
        <mesh filename="package://hey5_description/meshes/palm.stl" scale="1 1 1"/>
      </geometry>
      <material name="Hey5DarkGrey"/>
    </visual>
    <collision>
      <origin rpy="0 0 0" xyz="0 0 0"/>
      <geometry>
        <mesh filename="package://hey5_description/meshes/palm_collision.stl" scale="1 1 1"/>
      </geometry>
    </collision>
  </link>
  <gazebo reference="hand_palm_link">
    <material>Gazebo/Black</material>
  </gazebo>
  <joint name="hand_thumb_joint" type="revolute">
    <parent link="hand_palm_link"/>
    <child link="hand_thumb_link"/>
    <origin rpy="0 0 0" xyz="0 0 0"/>
    <axis xyz="0 0 1"/>
    <limit effort="2.0" lower="-2.61799387799" upper="6.28318530718" velocity="3.35"/>
    <dynamics damping="0.5" friction="0.0"/>
    <!-- TODO: Tune -->
    <safety_controller k_position="20" k_velocity="20" soft_lower_limit="-2.61799387799" soft_upper_limit="6.28318530718"/>
  </joint>
  <link name="hand_thumb_link">
    <inertial>
      <origin rpy="0 0 0" xyz="0 0 0"/>
      <mass value="0.05"/>
      <inertia ixx="0.001" ixy="0" ixz="0" iyy="0.001" iyz="0" izz="0.001"/>
      <!--To stabilize simulation-->
    </inertial>
    <visual>
      <origin rpy="0 0 0" xyz="0 0 0"/>
      <geometry>
        <sphere radius="0.001"/>
      </geometry>
      <material name="Hey5DarkGrey"/>
    </visual>
    <collision>
      <origin rpy="0 0 0" xyz="0 0 0"/>
      <geometry>
        <sphere radius="0.001"/>
      </geometry>
    </collision>
  </link>
  <transmission name="hand_thumb_trans">
    <type>transmission_interface/SimpleTransmission</type>
    <actuator name="hand_thumb_motor">
      <mechanicalReduction>1.0</mechanicalReduction>
    </actuator>
    <joint name="hand_thumb_joint">
      <!--<hardwareInterface>hardware_interface/PositionJointInterface</hardwareInterface>-->
      <hardwareInterface>hardware_interface/EffortJointInterface</hardwareInterface>
    </joint>
  </transmission>
  <joint name="hand_index_joint" type="revolute">
    <parent link="hand_palm_link"/>
    <child link="hand_index_link"/>
    <origin rpy="0 0 0" xyz="0 0 0"/>
    <axis xyz="0 0 1"/>
    <limit effort="2.0" lower="-3.05432619099" upper="6.80678408278" velocity="3.35"/>
    <dynamics damping="0.5" friction="0.0"/>
    <!-- TODO: Tune -->
    <safety_controller k_position="20" k_velocity="20" soft_lower_limit="-3.05432619099" soft_upper_limit="6.80678408278"/>
  </joint>
  <link name="hand_index_link">
    <inertial>
      <origin rpy="0 0 0" xyz="0 0 0"/>
      <mass value="0.05"/>
      <inertia ixx="0.001" ixy="0" ixz="0" iyy="0.001" iyz="0" izz="0.001"/>
      <!--To stabilize simulation-->
    </inertial>
    <visual>
      <origin rpy="0 0 0" xyz="0 0 0"/>
      <geometry>
        <sphere radius="0.001"/>
      </geometry>
      <material name="Hey5DarkGrey"/>
    </visual>
    <collision>
      <origin rpy="0 0 0" xyz="0 0 0"/>
      <geometry>
        <sphere radius="0.001"/>
      </geometry>
    </collision>
  </link>
  <transmission name="hand_index_trans">
    <type>transmission_interface/SimpleTransmission</type>
    <actuator name="hand_index_motor">
      <mechanicalReduction>1.0</mechanicalReduction>
    </actuator>
    <joint name="hand_index_joint">
      <!--<hardwareInterface>hardware_interface/PositionJointInterface</hardwareInterface>-->
      <hardwareInterface>hardware_interface/EffortJointInterface</hardwareInterface>
    </joint>
  </transmission>
  <joint name="hand_mrl_joint" type="revolute">
    <parent link="hand_palm_link"/>
    <child link="hand_mrl_link"/>
    <origin rpy="0 0 0" xyz="0 0 0"/>
    <axis xyz="0 0 1"/>
    <limit effort="2.0" lower="-2.53072741539" upper="9.25024503557" velocity="3.56"/>
    <dynamics damping="0.5" friction="0.0"/>
    <!-- TODO: Tune -->
    <safety_controller k_position="20" k_velocity="20" soft_lower_limit="-2.53072741539" soft_upper_limit="9.25024503557"/>
  </joint>
  <link name="hand_mrl_link">
    <inertial>
      <origin rpy="0 0 0" xyz="0 0 0"/>
      <mass value="0.05"/>
      <inertia ixx="0.001" ixy="0" ixz="0" iyy="0.001" iyz="0" izz="0.001"/>
      <!--To stabilize simulation-->
    </inertial>
    <visual>
      <origin rpy="0 0 0" xyz="0 0 0"/>
      <geometry>
        <sphere radius="0.001"/>
      </geometry>
      <material name="Hey5DarkGrey"/>
    </visual>
    <collision>
      <origin rpy="0 0 0" xyz="0 0 0"/>
      <geometry>
        <sphere radius="0.001"/>
      </geometry>
    </collision>
  </link>
  <transmission name="hand_mrl_trans">
    <type>transmission_interface/SimpleTransmission</type>
    <actuator name="hand_mrl_motor">
      <mechanicalReduction>1.0</mechanicalReduction>
    </actuator>
    <joint name="hand_mrl_joint">
      <!--<hardwareInterface>hardware_interface/PositionJointInterface</hardwareInterface>-->
      <hardwareInterface>hardware_interface/EffortJointInterface</hardwareInterface>
    </joint>
  </transmission>
  <joint name="hand_thumb_abd_joint" type="revolute">
    <parent link="hand_palm_link"/>
    <child link="hand_thumb_abd_link"/>
    <origin rpy="0 -1.1344640138 0" xyz="0.0901 0.0134 0.038"/>
    <axis xyz="0 0 1"/>
    <limit effort="2.0" lower="0.0" upper="1.57079632679" velocity="2.0"/>
    <dynamics damping="0.5" friction="0.0"/>
  </joint>
  <link name="hand_thumb_abd_link">
    <inertial>
      <origin rpy="0 0 0" xyz="-0.0132 0.0037 -0.0017"/>
      <mass value="0.014"/>
      <inertia ixx="0.001" ixy="0" ixz="0" iyy="0.001" iyz="0" izz="0.001"/>
      <!-- To stabilize simulation -->
    </inertial>
    <visual>
      <origin rpy="0 0 0" xyz="0 0 0"/>
      <geometry>
        <mesh filename="package://hey5_description/meshes/thumb_abd_collision.stl" scale="1 1 1"/>
      </geometry>
      <material name="Hey5DarkGrey"/>
    </visual>
    <collision>
      <origin rpy="0 0 0" xyz="0 0 0"/>
      <geometry>
        <mesh filename="package://hey5_description/meshes/thumb_abd_collision.stl" scale="1 1 1"/>
      </geometry>
    </collision>
  </link>
  <gazebo reference="hand_thumb_abd_link">
    <material>Gazebo/Black</material>
  </gazebo>
  <joint name="hand_thumb_virtual_1_joint" type="revolute">
    <parent link="hand_thumb_abd_link"/>
    <child link="hand_thumb_virtual_1_link"/>
    <origin rpy="-1.14423785761 0 0" xyz="0.0225 0.003 0"/>
    <axis xyz="0 0 1"/>
    <limit effort="2.0" lower="0.0" upper="0.785398163397" velocity="2.0"/>
    <dynamics damping="0.5" friction="0.0"/>
  </joint>
  <link name="hand_thumb_virtual_1_link">
    <inertial>
      <origin rpy="0 0 0" xyz="0.0065 0 0"/>
      <mass value="0.01"/>
      <!--TODO: can we make it zero and still have a stable dynamic simulation?-->
      <inertia ixx="0.001" ixy="0" ixz="0" iyy="0.001" iyz="0" izz="0.001"/>
      <!-- To stabilize simulation -->
    </inertial>
    <visual>
      <origin rpy="0 0 0" xyz="0.0065 0 0"/>
      <geometry>
        <box size="0.013 0.002 0.012"/>
      </geometry>
      <material name="Hey5DarkGrey"/>
    </visual>
    <collision>
      <origin rpy="0 0 0" xyz="0 0 0"/>
      <geometry>
        <box size="0.013 0.002 0.012"/>
      </geometry>
    </collision>
  </link>
  <gazebo reference="hand_thumb_virtual_1_link">
    <material>Gazebo/Black</material>
  </gazebo>
  <joint name="hand_thumb_flex_1_joint" type="revolute">
    <parent link="hand_thumb_virtual_1_link"/>
    <child link="hand_thumb_flex_1_link"/>
    <origin rpy="0 0 0" xyz="0.013 0 0"/>
    <axis xyz="0 0 1"/>
    <limit effort="2.0" lower="0.0" upper="0.785398163397" velocity="2.0"/>
    <dynamics damping="0.5" friction="0.0"/>
  </joint>
  <link name="hand_thumb_flex_1_link">
    <inertial>
      <origin rpy="0 0 0" xyz="0.0047 0.0031 0.0"/>
      <mass value="0.009"/>
      <inertia ixx="0.001" ixy="0" ixz="0" iyy="0.001" iyz="0" izz="0.001"/>
      <!-- To stabilize simulation -->
    </inertial>
    <visual>
      <origin rpy="0 0 0" xyz="0 0 0"/>
      <geometry>
        <mesh filename="package://hey5_description/meshes/finger_flex_collision.stl"/>
      </geometry>
      <material name="Hey5DarkGrey"/>
    </visual>
    <collision>
      <origin rpy="0 0 0" xyz="0 0 0"/>
      <geometry>
        <mesh filename="package://hey5_description/meshes/finger_flex_collision.stl"/>
      </geometry>
    </collision>
  </link>
  <gazebo reference="hand_thumb_flex_1_link">
    <material>Gazebo/Black</material>
  </gazebo>
  <joint name="hand_thumb_virtual_2_joint" type="revolute">
    <parent link="hand_thumb_flex_1_link"/>
    <child link="hand_thumb_virtual_2_link"/>
    <origin rpy="0 0 0" xyz="0.009 0 0"/>
    <axis xyz="0 0 1"/>
    <limit effort="2.0" lower="0.0" upper="0.785398163397" velocity="2.0"/>
    <dynamics damping="0.5" friction="0.0"/>
  </joint>
  <link name="hand_thumb_virtual_2_link">
    <inertial>
      <origin rpy="0 0 0" xyz="0.0065 0 0"/>
      <mass value="0.01"/>
      <!--TODO: can we make it zero and still have a stable dynamic simulation?-->
      <inertia ixx="0.001" ixy="0" ixz="0" iyy="0.001" iyz="0" izz="0.001"/>
      <!-- To stabilize simulation -->
    </inertial>
    <visual>
      <origin rpy="0 0 0" xyz="0.0065 0 0"/>
      <geometry>
        <box size="0.013 0.002 0.012"/>
      </geometry>
      <material name="Hey5DarkGrey"/>
    </visual>
    <collision>
      <origin rpy="0 0 0" xyz="0 0 0"/>
      <geometry>
        <box size="0.013 0.002 0.012"/>
      </geometry>
    </collision>
  </link>
  <gazebo reference="hand_thumb_virtual_2_link">
    <material>Gazebo/Black</material>
  </gazebo>
  <joint name="hand_thumb_flex_2_joint" type="revolute">
    <parent link="hand_thumb_virtual_2_link"/>
    <child link="hand_thumb_flex_2_link"/>
    <origin rpy="0 0 0" xyz="0.013 0 0"/>
    <axis xyz="0 0 1"/>
    <limit effort="2.0" lower="0.0" upper="0.785398163397" velocity="2.0"/>
    <dynamics damping="0.5" friction="0.0"/>
  </joint>
  <link name="hand_thumb_flex_2_link">
    <inertial>
      <origin rpy="0 0 0" xyz="0.0096 0.003 0.0"/>
      <mass value="0.015"/>
      <inertia ixx="0.001" ixy="0" ixz="0" iyy="0.001" iyz="0" izz="0.001"/>
      <!-- To stabilize simulation -->
    </inertial>
    <visual>
      <origin rpy="0 0 0" xyz="0 0 0"/>
      <geometry>
        <mesh filename="package://hey5_description/meshes/finger_flex_tip_collision.stl"/>
      </geometry>
      <material name="Hey5DarkGrey"/>
    </visual>
    <collision>
      <origin rpy="0 0 0" xyz="0 0 0"/>
      <geometry>
        <mesh filename="package://hey5_description/meshes/finger_flex_tip_collision.stl"/>
      </geometry>
    </collision>
  </link>
  <gazebo reference="hand_thumb_flex_2_link">
    <material>Gazebo/Black</material>
  </gazebo>
  <joint name="hand_index_abd_joint" type="revolute">
    <parent link="hand_palm_link"/>
    <child link="hand_index_abd_link"/>
    <origin rpy="-1.57079632679 -0.523598775598 0" xyz="0.1265 0.0042 0.0265"/>
    <axis xyz="0 0 1"/>
    <limit effort="2.0" lower="-0.523598775598" upper="0.523598775598" velocity="2.0"/>
    <dynamics damping="0.5" friction="0.0"/>
  </joint>
  <link name="hand_index_abd_link">
    <inertial>
      <origin rpy="0 0 0" xyz="-0.0018 0.0 0.0028"/>
      <mass value="0.018"/>
      <inertia ixx="0.001" ixy="0" ixz="0" iyy="0.001" iyz="0" izz="0.001"/>
      <!-- To stabilize simulation -->
    </inertial>
    <visual>
      <origin rpy="0 0 0" xyz="0 0 0"/>
      <geometry>
        <mesh filename="package://hey5_description/meshes/finger_abd_collision.stl" scale="1 1 1"/>
      </geometry>
      <material name="Hey5DarkGrey"/>
    </visual>
    <collision>
      <origin rpy="0 0 0" xyz="0 0 0"/>
      <geometry>
        <mesh filename="package://hey5_description/meshes/finger_abd_collision.stl" scale="1 1 1"/>
      </geometry>
    </collision>
  </link>
  <gazebo reference="hand_index_abd_link">
    <material>Gazebo/Black</material>
  </gazebo>
  <joint name="hand_index_virtual_1_joint" type="revolute">
    <parent link="hand_index_abd_link"/>
    <child link="hand_index_virtual_1_link"/>
    <origin rpy="1.57079632679 0 0" xyz="0.009 0 0"/>
    <axis xyz="0 0 1"/>
    <limit effort="2.0" lower="0.0" upper="0.785398163397" velocity="2.0"/>
    <dynamics damping="0.5" friction="0.0"/>
  </joint>
  <link name="hand_index_virtual_1_link">
    <inertial>
      <origin rpy="0 0 0" xyz="0.0065 0 0"/>
      <mass value="0.01"/>
      <!--TODO: can we make it zero and still have a stable dynamic simulation?-->
      <inertia ixx="0.001" ixy="0" ixz="0" iyy="0.001" iyz="0" izz="0.001"/>
      <!-- To stabilize simulation -->
    </inertial>
    <visual>
      <origin rpy="0 0 0" xyz="0.0065 0 0"/>
      <geometry>
        <box size="0.013 0.002 0.012"/>
      </geometry>
      <material name="Hey5DarkGrey"/>
    </visual>
    <collision>
      <origin rpy="0 0 0" xyz="0 0 0"/>
      <geometry>
        <box size="0.013 0.002 0.012"/>
      </geometry>
    </collision>
  </link>
  <gazebo reference="hand_index_virtual_1_link">
    <material>Gazebo/Black</material>
  </gazebo>
  <joint name="hand_index_flex_1_joint" type="revolute">
    <parent link="hand_index_virtual_1_link"/>
    <child link="hand_index_flex_1_link"/>
    <origin rpy="0 0 0" xyz="0.013 0 0"/>
    <axis xyz="0 0 1"/>
    <limit effort="2.0" lower="0.0" upper="0.785398163397" velocity="2.0"/>
    <dynamics damping="0.5" friction="0.0"/>
  </joint>
  <link name="hand_index_flex_1_link">
    <inertial>
      <origin rpy="0 0 0" xyz="0.0047 0.0031 0.0"/>
      <mass value="0.009"/>
      <inertia ixx="0.001" ixy="0" ixz="0" iyy="0.001" iyz="0" izz="0.001"/>
      <!-- To stabilize simulation -->
    </inertial>
    <visual>
      <origin rpy="0 0 0" xyz="0 0 0"/>
      <geometry>
        <mesh filename="package://hey5_description/meshes/finger_flex_collision.stl"/>
      </geometry>
      <material name="Hey5DarkGrey"/>
    </visual>
    <collision>
      <origin rpy="0 0 0" xyz="0 0 0"/>
      <geometry>
        <mesh filename="package://hey5_description/meshes/finger_flex_collision.stl"/>
      </geometry>
    </collision>
  </link>
  <gazebo reference="hand_index_flex_1_link">
    <material>Gazebo/Black</material>
  </gazebo>
  <joint name="hand_index_virtual_2_joint" type="revolute">
    <parent link="hand_index_flex_1_link"/>
    <child link="hand_index_virtual_2_link"/>
    <origin rpy="0 0 0" xyz="0.009 0 0"/>
    <axis xyz="0 0 1"/>
    <limit effort="2.0" lower="0.0" upper="0.785398163397" velocity="2.0"/>
    <dynamics damping="0.5" friction="0.0"/>
  </joint>
  <link name="hand_index_virtual_2_link">
    <inertial>
      <origin rpy="0 0 0" xyz="0.0065 0 0"/>
      <mass value="0.01"/>
      <!--TODO: can we make it zero and still have a stable dynamic simulation?-->
      <inertia ixx="0.001" ixy="0" ixz="0" iyy="0.001" iyz="0" izz="0.001"/>
      <!-- To stabilize simulation -->
    </inertial>
    <visual>
      <origin rpy="0 0 0" xyz="0.0065 0 0"/>
      <geometry>
        <box size="0.013 0.002 0.012"/>
      </geometry>
      <material name="Hey5DarkGrey"/>
    </visual>
    <collision>
      <origin rpy="0 0 0" xyz="0 0 0"/>
      <geometry>
        <box size="0.013 0.002 0.012"/>
      </geometry>
    </collision>
  </link>
  <gazebo reference="hand_index_virtual_2_link">
    <material>Gazebo/Black</material>
  </gazebo>
  <joint name="hand_index_flex_2_joint" type="revolute">
    <parent link="hand_index_virtual_2_link"/>
    <child link="hand_index_flex_2_link"/>
    <origin rpy="0 0 0" xyz="0.013 0 0"/>
    <axis xyz="0 0 1"/>
    <limit effort="2.0" lower="0.0" upper="0.785398163397" velocity="2.0"/>
    <dynamics damping="0.5" friction="0.0"/>
  </joint>
  <link name="hand_index_flex_2_link">
    <inertial>
      <origin rpy="0 0 0" xyz="0.0047 0.0031 0.0"/>
      <mass value="0.009"/>
      <inertia ixx="0.001" ixy="0" ixz="0" iyy="0.001" iyz="0" izz="0.001"/>
      <!-- To stabilize simulation -->
    </inertial>
    <visual>
      <origin rpy="0 0 0" xyz="0 0 0"/>
      <geometry>
        <mesh filename="package://hey5_description/meshes/finger_flex_collision.stl"/>
      </geometry>
      <material name="Hey5DarkGrey"/>
    </visual>
    <collision>
      <origin rpy="0 0 0" xyz="0 0 0"/>
      <geometry>
        <mesh filename="package://hey5_description/meshes/finger_flex_collision.stl"/>
      </geometry>
    </collision>
  </link>
  <gazebo reference="hand_index_flex_2_link">
    <material>Gazebo/Black</material>
  </gazebo>
  <joint name="hand_index_virtual_3_joint" type="revolute">
    <parent link="hand_index_flex_2_link"/>
    <child link="hand_index_virtual_3_link"/>
    <origin rpy="0 0 0" xyz="0.009 0 0"/>
    <axis xyz="0 0 1"/>
    <limit effort="2.0" lower="0.0" upper="0.785398163397" velocity="2.0"/>
    <dynamics damping="0.5" friction="0.0"/>
  </joint>
  <link name="hand_index_virtual_3_link">
    <inertial>
      <origin rpy="0 0 0" xyz="0.0065 0 0"/>
      <mass value="0.01"/>
      <!--TODO: can we make it zero and still have a stable dynamic simulation?-->
      <inertia ixx="0.001" ixy="0" ixz="0" iyy="0.001" iyz="0" izz="0.001"/>
      <!-- To stabilize simulation -->
    </inertial>
    <visual>
      <origin rpy="0 0 0" xyz="0.0065 0 0"/>
      <geometry>
        <box size="0.013 0.002 0.012"/>
      </geometry>
      <material name="Hey5DarkGrey"/>
    </visual>
    <collision>
      <origin rpy="0 0 0" xyz="0 0 0"/>
      <geometry>
        <box size="0.013 0.002 0.012"/>
      </geometry>
    </collision>
  </link>
  <gazebo reference="hand_index_virtual_3_link">
    <material>Gazebo/Black</material>
  </gazebo>
  <joint name="hand_index_flex_3_joint" type="revolute">
    <parent link="hand_index_virtual_3_link"/>
    <child link="hand_index_flex_3_link"/>
    <origin rpy="0 0 0" xyz="0.013 0 0"/>
    <axis xyz="0 0 1"/>
    <limit effort="2.0" lower="0.0" upper="0.785398163397" velocity="2.0"/>
    <dynamics damping="0.5" friction="0.0"/>
  </joint>
  <link name="hand_index_flex_3_link">
    <inertial>
      <origin rpy="0 0 0" xyz="0.0096 0.003 0.0"/>
      <mass value="0.015"/>
      <inertia ixx="0.001" ixy="0" ixz="0" iyy="0.001" iyz="0" izz="0.001"/>
      <!-- To stabilize simulation -->
    </inertial>
    <visual>
      <origin rpy="0 0 0" xyz="0 0 0"/>
      <geometry>
        <mesh filename="package://hey5_description/meshes/finger_flex_tip_collision.stl"/>
      </geometry>
      <material name="Hey5DarkGrey"/>
    </visual>
    <collision>
      <origin rpy="0 0 0" xyz="0 0 0"/>
      <geometry>
        <mesh filename="package://hey5_description/meshes/finger_flex_tip_collision.stl"/>
      </geometry>
    </collision>
  </link>
  <gazebo reference="hand_index_flex_3_link">
    <material>Gazebo/Black</material>
  </gazebo>
  <joint name="hand_middle_abd_joint" type="revolute">
    <parent link="hand_palm_link"/>
    <child link="hand_middle_abd_link"/>
    <origin rpy="-1.57079632679 0 0" xyz="0.1335 0.0042 0.007"/>
    <axis xyz="0 0 1"/>
    <limit effort="2.0" lower="-0.523598775598" upper="0.523598775598" velocity="2.0"/>
    <dynamics damping="0.5" friction="0.0"/>
  </joint>
  <link name="hand_middle_abd_link">
    <inertial>
      <origin rpy="0 0 0" xyz="-0.0018 0.0 0.0028"/>
      <mass value="0.018"/>
      <inertia ixx="0.001" ixy="0" ixz="0" iyy="0.001" iyz="0" izz="0.001"/>
      <!-- To stabilize simulation -->
    </inertial>
    <visual>
      <origin rpy="0 0 0" xyz="0 0 0"/>
      <geometry>
        <mesh filename="package://hey5_description/meshes/finger_abd_collision.stl" scale="1 1 1"/>
      </geometry>
      <material name="Hey5DarkGrey"/>
    </visual>
    <collision>
      <origin rpy="0 0 0" xyz="0 0 0"/>
      <geometry>
        <mesh filename="package://hey5_description/meshes/finger_abd_collision.stl" scale="1 1 1"/>
      </geometry>
    </collision>
  </link>
  <gazebo reference="hand_middle_abd_link">
    <material>Gazebo/Black</material>
  </gazebo>
  <joint name="hand_middle_virtual_1_joint" type="revolute">
    <parent link="hand_middle_abd_link"/>
    <child link="hand_middle_virtual_1_link"/>
    <origin rpy="1.57079632679 0 0" xyz="0.009 0 0"/>
    <axis xyz="0 0 1"/>
    <limit effort="2.0" lower="0.0" upper="0.785398163397" velocity="2.0"/>
    <dynamics damping="0.5" friction="0.0"/>
  </joint>
  <link name="hand_middle_virtual_1_link">
    <inertial>
      <origin rpy="0 0 0" xyz="0.0065 0 0"/>
      <mass value="0.01"/>
      <!--TODO: can we make it zero and still have a stable dynamic simulation?-->
      <inertia ixx="0.001" ixy="0" ixz="0" iyy="0.001" iyz="0" izz="0.001"/>
      <!-- To stabilize simulation -->
    </inertial>
    <visual>
      <origin rpy="0 0 0" xyz="0.0065 0 0"/>
      <geometry>
        <box size="0.013 0.002 0.012"/>
      </geometry>
      <material name="Hey5DarkGrey"/>
    </visual>
    <collision>
      <origin rpy="0 0 0" xyz="0 0 0"/>
      <geometry>
        <box size="0.013 0.002 0.012"/>
      </geometry>
    </collision>
  </link>
  <gazebo reference="hand_middle_virtual_1_link">
    <material>Gazebo/Black</material>
  </gazebo>
  <joint name="hand_middle_flex_1_joint" type="revolute">
    <parent link="hand_middle_virtual_1_link"/>
    <child link="hand_middle_flex_1_link"/>
    <origin rpy="0 0 0" xyz="0.013 0 0"/>
    <axis xyz="0 0 1"/>
    <limit effort="2.0" lower="0.0" upper="0.785398163397" velocity="2.0"/>
    <dynamics damping="0.5" friction="0.0"/>
  </joint>
  <link name="hand_middle_flex_1_link">
    <inertial>
      <origin rpy="0 0 0" xyz="0.0047 0.0031 0.0"/>
      <mass value="0.009"/>
      <inertia ixx="0.001" ixy="0" ixz="0" iyy="0.001" iyz="0" izz="0.001"/>
      <!-- To stabilize simulation -->
    </inertial>
    <visual>
      <origin rpy="0 0 0" xyz="0 0 0"/>
      <geometry>
        <mesh filename="package://hey5_description/meshes/finger_flex_collision.stl"/>
      </geometry>
      <material name="Hey5DarkGrey"/>
    </visual>
    <collision>
      <origin rpy="0 0 0" xyz="0 0 0"/>
      <geometry>
        <mesh filename="package://hey5_description/meshes/finger_flex_collision.stl"/>
      </geometry>
    </collision>
  </link>
  <gazebo reference="hand_middle_flex_1_link">
    <material>Gazebo/Black</material>
  </gazebo>
  <joint name="hand_middle_virtual_2_joint" type="revolute">
    <parent link="hand_middle_flex_1_link"/>
    <child link="hand_middle_virtual_2_link"/>
    <origin rpy="0 0 0" xyz="0.009 0 0"/>
    <axis xyz="0 0 1"/>
    <limit effort="2.0" lower="0.0" upper="0.785398163397" velocity="2.0"/>
    <dynamics damping="0.5" friction="0.0"/>
  </joint>
  <link name="hand_middle_virtual_2_link">
    <inertial>
      <origin rpy="0 0 0" xyz="0.0065 0 0"/>
      <mass value="0.01"/>
      <!--TODO: can we make it zero and still have a stable dynamic simulation?-->
      <inertia ixx="0.001" ixy="0" ixz="0" iyy="0.001" iyz="0" izz="0.001"/>
      <!-- To stabilize simulation -->
    </inertial>
    <visual>
      <origin rpy="0 0 0" xyz="0.0065 0 0"/>
      <geometry>
        <box size="0.013 0.002 0.012"/>
      </geometry>
      <material name="Hey5DarkGrey"/>
    </visual>
    <collision>
      <origin rpy="0 0 0" xyz="0 0 0"/>
      <geometry>
        <box size="0.013 0.002 0.012"/>
      </geometry>
    </collision>
  </link>
  <gazebo reference="hand_middle_virtual_2_link">
    <material>Gazebo/Black</material>
  </gazebo>
  <joint name="hand_middle_flex_2_joint" type="revolute">
    <parent link="hand_middle_virtual_2_link"/>
    <child link="hand_middle_flex_2_link"/>
    <origin rpy="0 0 0" xyz="0.013 0 0"/>
    <axis xyz="0 0 1"/>
    <limit effort="2.0" lower="0.0" upper="0.785398163397" velocity="2.0"/>
    <dynamics damping="0.5" friction="0.0"/>
  </joint>
  <link name="hand_middle_flex_2_link">
    <inertial>
      <origin rpy="0 0 0" xyz="0.0047 0.0031 0.0"/>
      <mass value="0.009"/>
      <inertia ixx="0.001" ixy="0" ixz="0" iyy="0.001" iyz="0" izz="0.001"/>
      <!-- To stabilize simulation -->
    </inertial>
    <visual>
      <origin rpy="0 0 0" xyz="0 0 0"/>
      <geometry>
        <mesh filename="package://hey5_description/meshes/finger_flex_collision.stl"/>
      </geometry>
      <material name="Hey5DarkGrey"/>
    </visual>
    <collision>
      <origin rpy="0 0 0" xyz="0 0 0"/>
      <geometry>
        <mesh filename="package://hey5_description/meshes/finger_flex_collision.stl"/>
      </geometry>
    </collision>
  </link>
  <gazebo reference="hand_middle_flex_2_link">
    <material>Gazebo/Black</material>
  </gazebo>
  <joint name="hand_middle_virtual_3_joint" type="revolute">
    <parent link="hand_middle_flex_2_link"/>
    <child link="hand_middle_virtual_3_link"/>
    <origin rpy="0 0 0" xyz="0.009 0 0"/>
    <axis xyz="0 0 1"/>
    <limit effort="2.0" lower="0.0" upper="0.785398163397" velocity="2.0"/>
    <dynamics damping="0.5" friction="0.0"/>
  </joint>
  <link name="hand_middle_virtual_3_link">
    <inertial>
      <origin rpy="0 0 0" xyz="0.0065 0 0"/>
      <mass value="0.01"/>
      <!--TODO: can we make it zero and still have a stable dynamic simulation?-->
      <inertia ixx="0.001" ixy="0" ixz="0" iyy="0.001" iyz="0" izz="0.001"/>
      <!-- To stabilize simulation -->
    </inertial>
    <visual>
      <origin rpy="0 0 0" xyz="0.0065 0 0"/>
      <geometry>
        <box size="0.013 0.002 0.012"/>
      </geometry>
      <material name="Hey5DarkGrey"/>
    </visual>
    <collision>
      <origin rpy="0 0 0" xyz="0 0 0"/>
      <geometry>
        <box size="0.013 0.002 0.012"/>
      </geometry>
    </collision>
  </link>
  <gazebo reference="hand_middle_virtual_3_link">
    <material>Gazebo/Black</material>
  </gazebo>
  <joint name="hand_middle_flex_3_joint" type="revolute">
    <parent link="hand_middle_virtual_3_link"/>
    <child link="hand_middle_flex_3_link"/>
    <origin rpy="0 0 0" xyz="0.013 0 0"/>
    <axis xyz="0 0 1"/>
    <limit effort="2.0" lower="0.0" upper="0.785398163397" velocity="2.0"/>
    <dynamics damping="0.5" friction="0.0"/>
  </joint>
  <link name="hand_middle_flex_3_link">
    <inertial>
      <origin rpy="0 0 0" xyz="0.0096 0.003 0.0"/>
      <mass value="0.015"/>
      <inertia ixx="0.001" ixy="0" ixz="0" iyy="0.001" iyz="0" izz="0.001"/>
      <!-- To stabilize simulation -->
    </inertial>
    <visual>
      <origin rpy="0 0 0" xyz="0 0 0"/>
      <geometry>
        <mesh filename="package://hey5_description/meshes/finger_flex_tip_collision.stl"/>
      </geometry>
      <material name="Hey5DarkGrey"/>
    </visual>
    <collision>
      <origin rpy="0 0 0" xyz="0 0 0"/>
      <geometry>
        <mesh filename="package://hey5_description/meshes/finger_flex_tip_collision.stl"/>
      </geometry>
    </collision>
  </link>
  <gazebo reference="hand_middle_flex_3_link">
    <material>Gazebo/Black</material>
  </gazebo>
  <joint name="hand_ring_abd_joint" type="revolute">
    <parent link="hand_palm_link"/>
    <child link="hand_ring_abd_link"/>
    <origin rpy="-1.57079632679 0.261799387799 0" xyz="0.1265 0.0042 -0.0125"/>
    <axis xyz="0 0 1"/>
    <limit effort="2.0" lower="-0.523598775598" upper="0.523598775598" velocity="2.0"/>
    <dynamics damping="0.5" friction="0.0"/>
  </joint>
  <link name="hand_ring_abd_link">
    <inertial>
      <origin rpy="0 0 0" xyz="-0.0018 0.0 0.0028"/>
      <mass value="0.018"/>
      <inertia ixx="0.001" ixy="0" ixz="0" iyy="0.001" iyz="0" izz="0.001"/>
      <!-- To stabilize simulation -->
    </inertial>
    <visual>
      <origin rpy="0 0 0" xyz="0 0 0"/>
      <geometry>
        <mesh filename="package://hey5_description/meshes/finger_abd_collision.stl" scale="1 1 1"/>
      </geometry>
      <material name="Hey5DarkGrey"/>
    </visual>
    <collision>
      <origin rpy="0 0 0" xyz="0 0 0"/>
      <geometry>
        <mesh filename="package://hey5_description/meshes/finger_abd_collision.stl" scale="1 1 1"/>
      </geometry>
    </collision>
  </link>
  <gazebo reference="hand_ring_abd_link">
    <material>Gazebo/Black</material>
  </gazebo>
  <joint name="hand_ring_virtual_1_joint" type="revolute">
    <parent link="hand_ring_abd_link"/>
    <child link="hand_ring_virtual_1_link"/>
    <origin rpy="1.57079632679 0 0" xyz="0.009 0 0"/>
    <axis xyz="0 0 1"/>
    <limit effort="2.0" lower="0.0" upper="0.785398163397" velocity="2.0"/>
    <dynamics damping="0.5" friction="0.0"/>
  </joint>
  <link name="hand_ring_virtual_1_link">
    <inertial>
      <origin rpy="0 0 0" xyz="0.0065 0 0"/>
      <mass value="0.01"/>
      <!--TODO: can we make it zero and still have a stable dynamic simulation?-->
      <inertia ixx="0.001" ixy="0" ixz="0" iyy="0.001" iyz="0" izz="0.001"/>
      <!-- To stabilize simulation -->
    </inertial>
    <visual>
      <origin rpy="0 0 0" xyz="0.0065 0 0"/>
      <geometry>
        <box size="0.013 0.002 0.012"/>
      </geometry>
      <material name="Hey5DarkGrey"/>
    </visual>
    <collision>
      <origin rpy="0 0 0" xyz="0 0 0"/>
      <geometry>
        <box size="0.013 0.002 0.012"/>
      </geometry>
    </collision>
  </link>
  <gazebo reference="hand_ring_virtual_1_link">
    <material>Gazebo/Black</material>
  </gazebo>
  <joint name="hand_ring_flex_1_joint" type="revolute">
    <parent link="hand_ring_virtual_1_link"/>
    <child link="hand_ring_flex_1_link"/>
    <origin rpy="0 0 0" xyz="0.013 0 0"/>
    <axis xyz="0 0 1"/>
    <limit effort="2.0" lower="0.0" upper="0.785398163397" velocity="2.0"/>
    <dynamics damping="0.5" friction="0.0"/>
  </joint>
  <link name="hand_ring_flex_1_link">
    <inertial>
      <origin rpy="0 0 0" xyz="0.0047 0.0031 0.0"/>
      <mass value="0.009"/>
      <inertia ixx="0.001" ixy="0" ixz="0" iyy="0.001" iyz="0" izz="0.001"/>
      <!-- To stabilize simulation -->
    </inertial>
    <visual>
      <origin rpy="0 0 0" xyz="0 0 0"/>
      <geometry>
        <mesh filename="package://hey5_description/meshes/finger_flex_collision.stl"/>
      </geometry>
      <material name="Hey5DarkGrey"/>
    </visual>
    <collision>
      <origin rpy="0 0 0" xyz="0 0 0"/>
      <geometry>
        <mesh filename="package://hey5_description/meshes/finger_flex_collision.stl"/>
      </geometry>
    </collision>
  </link>
  <gazebo reference="hand_ring_flex_1_link">
    <material>Gazebo/Black</material>
  </gazebo>
  <joint name="hand_ring_virtual_2_joint" type="revolute">
    <parent link="hand_ring_flex_1_link"/>
    <child link="hand_ring_virtual_2_link"/>
    <origin rpy="0 0 0" xyz="0.009 0 0"/>
    <axis xyz="0 0 1"/>
    <limit effort="2.0" lower="0.0" upper="0.785398163397" velocity="2.0"/>
    <dynamics damping="0.5" friction="0.0"/>
  </joint>
  <link name="hand_ring_virtual_2_link">
    <inertial>
      <origin rpy="0 0 0" xyz="0.0065 0 0"/>
      <mass value="0.01"/>
      <!--TODO: can we make it zero and still have a stable dynamic simulation?-->
      <inertia ixx="0.001" ixy="0" ixz="0" iyy="0.001" iyz="0" izz="0.001"/>
      <!-- To stabilize simulation -->
    </inertial>
    <visual>
      <origin rpy="0 0 0" xyz="0.0065 0 0"/>
      <geometry>
        <box size="0.013 0.002 0.012"/>
      </geometry>
      <material name="Hey5DarkGrey"/>
    </visual>
    <collision>
      <origin rpy="0 0 0" xyz="0 0 0"/>
      <geometry>
        <box size="0.013 0.002 0.012"/>
      </geometry>
    </collision>
  </link>
  <gazebo reference="hand_ring_virtual_2_link">
    <material>Gazebo/Black</material>
  </gazebo>
  <joint name="hand_ring_flex_2_joint" type="revolute">
    <parent link="hand_ring_virtual_2_link"/>
    <child link="hand_ring_flex_2_link"/>
    <origin rpy="0 0 0" xyz="0.013 0 0"/>
    <axis xyz="0 0 1"/>
    <limit effort="2.0" lower="0.0" upper="0.785398163397" velocity="2.0"/>
    <dynamics damping="0.5" friction="0.0"/>
  </joint>
  <link name="hand_ring_flex_2_link">
    <inertial>
      <origin rpy="0 0 0" xyz="0.0047 0.0031 0.0"/>
      <mass value="0.009"/>
      <inertia ixx="0.001" ixy="0" ixz="0" iyy="0.001" iyz="0" izz="0.001"/>
      <!-- To stabilize simulation -->
    </inertial>
    <visual>
      <origin rpy="0 0 0" xyz="0 0 0"/>
      <geometry>
        <mesh filename="package://hey5_description/meshes/finger_flex_collision.stl"/>
      </geometry>
      <material name="Hey5DarkGrey"/>
    </visual>
    <collision>
      <origin rpy="0 0 0" xyz="0 0 0"/>
      <geometry>
        <mesh filename="package://hey5_description/meshes/finger_flex_collision.stl"/>
      </geometry>
    </collision>
  </link>
  <gazebo reference="hand_ring_flex_2_link">
    <material>Gazebo/Black</material>
  </gazebo>
  <joint name="hand_ring_virtual_3_joint" type="revolute">
    <parent link="hand_ring_flex_2_link"/>
    <child link="hand_ring_virtual_3_link"/>
    <origin rpy="0 0 0" xyz="0.009 0 0"/>
    <axis xyz="0 0 1"/>
    <limit effort="2.0" lower="0.0" upper="0.785398163397" velocity="2.0"/>
    <dynamics damping="0.5" friction="0.0"/>
  </joint>
  <link name="hand_ring_virtual_3_link">
    <inertial>
      <origin rpy="0 0 0" xyz="0.0065 0 0"/>
      <mass value="0.01"/>
      <!--TODO: can we make it zero and still have a stable dynamic simulation?-->
      <inertia ixx="0.001" ixy="0" ixz="0" iyy="0.001" iyz="0" izz="0.001"/>
      <!-- To stabilize simulation -->
    </inertial>
    <visual>
      <origin rpy="0 0 0" xyz="0.0065 0 0"/>
      <geometry>
        <box size="0.013 0.002 0.012"/>
      </geometry>
      <material name="Hey5DarkGrey"/>
    </visual>
    <collision>
      <origin rpy="0 0 0" xyz="0 0 0"/>
      <geometry>
        <box size="0.013 0.002 0.012"/>
      </geometry>
    </collision>
  </link>
  <gazebo reference="hand_ring_virtual_3_link">
    <material>Gazebo/Black</material>
  </gazebo>
  <joint name="hand_ring_flex_3_joint" type="revolute">
    <parent link="hand_ring_virtual_3_link"/>
    <child link="hand_ring_flex_3_link"/>
    <origin rpy="0 0 0" xyz="0.013 0 0"/>
    <axis xyz="0 0 1"/>
    <limit effort="2.0" lower="0.0" upper="0.785398163397" velocity="2.0"/>
    <dynamics damping="0.5" friction="0.0"/>
  </joint>
  <link name="hand_ring_flex_3_link">
    <inertial>
      <origin rpy="0 0 0" xyz="0.0096 0.003 0.0"/>
      <mass value="0.015"/>
      <inertia ixx="0.001" ixy="0" ixz="0" iyy="0.001" iyz="0" izz="0.001"/>
      <!-- To stabilize simulation -->
    </inertial>
    <visual>
      <origin rpy="0 0 0" xyz="0 0 0"/>
      <geometry>
        <mesh filename="package://hey5_description/meshes/finger_flex_tip_collision.stl"/>
      </geometry>
      <material name="Hey5DarkGrey"/>
    </visual>
    <collision>
      <origin rpy="0 0 0" xyz="0 0 0"/>
      <geometry>
        <mesh filename="package://hey5_description/meshes/finger_flex_tip_collision.stl"/>
      </geometry>
    </collision>
  </link>
  <gazebo reference="hand_ring_flex_3_link">
    <material>Gazebo/Black</material>
  </gazebo>
  <joint name="hand_little_abd_joint" type="revolute">
    <parent link="hand_palm_link"/>
    <child link="hand_little_abd_link"/>
    <origin rpy="-1.57079632679 0.523598775598 0" xyz="0.1165 0.0042 -0.032"/>
    <axis xyz="0 0 1"/>
    <limit effort="2.0" lower="-0.523598775598" upper="0.523598775598" velocity="2.0"/>
    <dynamics damping="0.5" friction="0.0"/>
  </joint>
  <link name="hand_little_abd_link">
    <inertial>
      <origin rpy="0 0 0" xyz="-0.0018 0.0 0.0028"/>
      <mass value="0.018"/>
      <inertia ixx="0.001" ixy="0" ixz="0" iyy="0.001" iyz="0" izz="0.001"/>
      <!-- To stabilize simulation -->
    </inertial>
    <visual>
      <origin rpy="0 0 0" xyz="0 0 0"/>
      <geometry>
        <mesh filename="package://hey5_description/meshes/finger_abd_collision.stl" scale="1 1 1"/>
      </geometry>
      <material name="Hey5DarkGrey"/>
    </visual>
    <collision>
      <origin rpy="0 0 0" xyz="0 0 0"/>
      <geometry>
        <mesh filename="package://hey5_description/meshes/finger_abd_collision.stl" scale="1 1 1"/>
      </geometry>
    </collision>
  </link>
  <gazebo reference="hand_little_abd_link">
    <material>Gazebo/Black</material>
  </gazebo>
  <joint name="hand_little_virtual_1_joint" type="revolute">
    <parent link="hand_little_abd_link"/>
    <child link="hand_little_virtual_1_link"/>
    <origin rpy="1.57079632679 0 0" xyz="0.009 0 0"/>
    <axis xyz="0 0 1"/>
    <limit effort="2.0" lower="0.0" upper="0.785398163397" velocity="2.0"/>
    <dynamics damping="0.5" friction="0.0"/>
  </joint>
  <link name="hand_little_virtual_1_link">
    <inertial>
      <origin rpy="0 0 0" xyz="0.0065 0 0"/>
      <mass value="0.01"/>
      <!--TODO: can we make it zero and still have a stable dynamic simulation?-->
      <inertia ixx="0.001" ixy="0" ixz="0" iyy="0.001" iyz="0" izz="0.001"/>
      <!-- To stabilize simulation -->
    </inertial>
    <visual>
      <origin rpy="0 0 0" xyz="0.0065 0 0"/>
      <geometry>
        <box size="0.013 0.002 0.012"/>
      </geometry>
      <material name="Hey5DarkGrey"/>
    </visual>
    <collision>
      <origin rpy="0 0 0" xyz="0 0 0"/>
      <geometry>
        <box size="0.013 0.002 0.012"/>
      </geometry>
    </collision>
  </link>
  <gazebo reference="hand_little_virtual_1_link">
    <material>Gazebo/Black</material>
  </gazebo>
  <joint name="hand_little_flex_1_joint" type="revolute">
    <parent link="hand_little_virtual_1_link"/>
    <child link="hand_little_flex_1_link"/>
    <origin rpy="0 0 0" xyz="0.013 0 0"/>
    <axis xyz="0 0 1"/>
    <limit effort="2.0" lower="0.0" upper="0.785398163397" velocity="2.0"/>
    <dynamics damping="0.5" friction="0.0"/>
  </joint>
  <link name="hand_little_flex_1_link">
    <inertial>
      <origin rpy="0 0 0" xyz="0.0047 0.0031 0.0"/>
      <mass value="0.009"/>
      <inertia ixx="0.001" ixy="0" ixz="0" iyy="0.001" iyz="0" izz="0.001"/>
      <!-- To stabilize simulation -->
    </inertial>
    <visual>
      <origin rpy="0 0 0" xyz="0 0 0"/>
      <geometry>
        <mesh filename="package://hey5_description/meshes/finger_flex_collision.stl"/>
      </geometry>
      <material name="Hey5DarkGrey"/>
    </visual>
    <collision>
      <origin rpy="0 0 0" xyz="0 0 0"/>
      <geometry>
        <mesh filename="package://hey5_description/meshes/finger_flex_collision.stl"/>
      </geometry>
    </collision>
  </link>
  <gazebo reference="hand_little_flex_1_link">
    <material>Gazebo/Black</material>
  </gazebo>
  <joint name="hand_little_virtual_2_joint" type="revolute">
    <parent link="hand_little_flex_1_link"/>
    <child link="hand_little_virtual_2_link"/>
    <origin rpy="0 0 0" xyz="0.009 0 0"/>
    <axis xyz="0 0 1"/>
    <limit effort="2.0" lower="0.0" upper="0.785398163397" velocity="2.0"/>
    <dynamics damping="0.5" friction="0.0"/>
  </joint>
  <link name="hand_little_virtual_2_link">
    <inertial>
      <origin rpy="0 0 0" xyz="0.0065 0 0"/>
      <mass value="0.01"/>
      <!--TODO: can we make it zero and still have a stable dynamic simulation?-->
      <inertia ixx="0.001" ixy="0" ixz="0" iyy="0.001" iyz="0" izz="0.001"/>
      <!-- To stabilize simulation -->
    </inertial>
    <visual>
      <origin rpy="0 0 0" xyz="0.0065 0 0"/>
      <geometry>
        <box size="0.013 0.002 0.012"/>
      </geometry>
      <material name="Hey5DarkGrey"/>
    </visual>
    <collision>
      <origin rpy="0 0 0" xyz="0 0 0"/>
      <geometry>
        <box size="0.013 0.002 0.012"/>
      </geometry>
    </collision>
  </link>
  <gazebo reference="hand_little_virtual_2_link">
    <material>Gazebo/Black</material>
  </gazebo>
  <joint name="hand_little_flex_2_joint" type="revolute">
    <parent link="hand_little_virtual_2_link"/>
    <child link="hand_little_flex_2_link"/>
    <origin rpy="0 0 0" xyz="0.013 0 0"/>
    <axis xyz="0 0 1"/>
    <limit effort="2.0" lower="0.0" upper="0.785398163397" velocity="2.0"/>
    <dynamics damping="0.5" friction="0.0"/>
  </joint>
  <link name="hand_little_flex_2_link">
    <inertial>
      <origin rpy="0 0 0" xyz="0.0047 0.0031 0.0"/>
      <mass value="0.009"/>
      <inertia ixx="0.001" ixy="0" ixz="0" iyy="0.001" iyz="0" izz="0.001"/>
      <!-- To stabilize simulation -->
    </inertial>
    <visual>
      <origin rpy="0 0 0" xyz="0 0 0"/>
      <geometry>
        <mesh filename="package://hey5_description/meshes/finger_flex_collision.stl"/>
      </geometry>
      <material name="Hey5DarkGrey"/>
    </visual>
    <collision>
      <origin rpy="0 0 0" xyz="0 0 0"/>
      <geometry>
        <mesh filename="package://hey5_description/meshes/finger_flex_collision.stl"/>
      </geometry>
    </collision>
  </link>
  <gazebo reference="hand_little_flex_2_link">
    <material>Gazebo/Black</material>
  </gazebo>
  <joint name="hand_little_virtual_3_joint" type="revolute">
    <parent link="hand_little_flex_2_link"/>
    <child link="hand_little_virtual_3_link"/>
    <origin rpy="0 0 0" xyz="0.009 0 0"/>
    <axis xyz="0 0 1"/>
    <limit effort="2.0" lower="0.0" upper="0.785398163397" velocity="2.0"/>
    <dynamics damping="0.5" friction="0.0"/>
  </joint>
  <link name="hand_little_virtual_3_link">
    <inertial>
      <origin rpy="0 0 0" xyz="0.0065 0 0"/>
      <mass value="0.01"/>
      <!--TODO: can we make it zero and still have a stable dynamic simulation?-->
      <inertia ixx="0.001" ixy="0" ixz="0" iyy="0.001" iyz="0" izz="0.001"/>
      <!-- To stabilize simulation -->
    </inertial>
    <visual>
      <origin rpy="0 0 0" xyz="0.0065 0 0"/>
      <geometry>
        <box size="0.013 0.002 0.012"/>
      </geometry>
      <material name="Hey5DarkGrey"/>
    </visual>
    <collision>
      <origin rpy="0 0 0" xyz="0 0 0"/>
      <geometry>
        <box size="0.013 0.002 0.012"/>
      </geometry>
    </collision>
  </link>
  <gazebo reference="hand_little_virtual_3_link">
    <material>Gazebo/Black</material>
  </gazebo>
  <joint name="hand_little_flex_3_joint" type="revolute">
    <parent link="hand_little_virtual_3_link"/>
    <child link="hand_little_flex_3_link"/>
    <origin rpy="0 0 0" xyz="0.013 0 0"/>
    <axis xyz="0 0 1"/>
    <limit effort="2.0" lower="0.0" upper="0.785398163397" velocity="2.0"/>
    <dynamics damping="0.5" friction="0.0"/>
  </joint>
  <link name="hand_little_flex_3_link">
    <inertial>
      <origin rpy="0 0 0" xyz="0.0096 0.003 0.0"/>
      <mass value="0.015"/>
      <inertia ixx="0.001" ixy="0" ixz="0" iyy="0.001" iyz="0" izz="0.001"/>
      <!-- To stabilize simulation -->
    </inertial>
    <visual>
      <origin rpy="0 0 0" xyz="0 0 0"/>
      <geometry>
        <mesh filename="package://hey5_description/meshes/finger_flex_tip_collision.stl"/>
      </geometry>
      <material name="Hey5DarkGrey"/>
    </visual>
    <collision>
      <origin rpy="0 0 0" xyz="0 0 0"/>
      <geometry>
        <mesh filename="package://hey5_description/meshes/finger_flex_tip_collision.stl"/>
      </geometry>
    </collision>
  </link>
  <gazebo reference="hand_little_flex_3_link">
    <material>Gazebo/Black</material>
  </gazebo>
  <!--Abductor-->
  <transmission name="hand_thumb_abd_trans">
    <type>hey5_transmissions/Hey5Reducer</type>
    <joint name="hand_thumb_abd_joint">
      <saturationLower>0.0</saturationLower>
      <saturationUpper>1.57079632679</saturationUpper>
      <!--<hardwareInterface>hardware_interface/JointStateInterface</hardwareInterface>-->
      <hardwareInterface>hardware_interface/EffortJointInterface</hardwareInterface>
    </joint>
    <actuator name="hand_thumb_motor">
      <mechanicalReduction>0.654498469498</mechanicalReduction>
    </actuator>
  </transmission>
  <!--First flexor-->
  <transmission name="hand_thumb_virtual_1_trans">
    <type>hey5_transmissions/Hey5Reducer</type>
    <joint name="hand_thumb_virtual_1_joint">
      <saturationLower>0.0</saturationLower>
      <deadBandUpper>2.0</deadBandUpper>
      <!--<hardwareInterface>hardware_interface/JointStateInterface</hardwareInterface>-->
      <hardwareInterface>hardware_interface/EffortJointInterface</hardwareInterface>
    </joint>
    <actuator name="hand_thumb_motor">
      <mechanicalReduction>0.162993578547</mechanicalReduction>
    </actuator>
  </transmission>
  <transmission name="hand_thumb_flex_1_trans">
    <type>hey5_transmissions/Hey5Reducer</type>
    <joint name="hand_thumb_flex_1_joint">
      <saturationLower>0.0</saturationLower>
      <deadBandUpper>2.0</deadBandUpper>
      <!--<hardwareInterface>hardware_interface/JointStateInterface</hardwareInterface>-->
      <hardwareInterface>hardware_interface/EffortJointInterface</hardwareInterface>
    </joint>
    <actuator name="hand_thumb_motor">
      <mechanicalReduction>0.162993578547</mechanicalReduction>
    </actuator>
  </transmission>
  <!--Second flexor-->
  <transmission name="hand_thumb_virtual_2_trans">
    <type>hey5_transmissions/Hey5Reducer</type>
    <joint name="hand_thumb_virtual_2_joint">
      <saturationLower>0.0</saturationLower>
      <deadBandUpper>2.0</deadBandUpper>
      <!--<hardwareInterface>hardware_interface/JointStateInterface</hardwareInterface>-->
      <hardwareInterface>hardware_interface/EffortJointInterface</hardwareInterface>
    </joint>
    <actuator name="hand_thumb_motor">
      <mechanicalReduction>0.162993578547</mechanicalReduction>
    </actuator>
  </transmission>
  <transmission name="hand_thumb_flex_2_trans">
    <type>hey5_transmissions/Hey5Reducer</type>
    <joint name="hand_thumb_flex_2_joint">
      <saturationLower>0.0</saturationLower>
      <deadBandUpper>2.0</deadBandUpper>
      <!--<hardwareInterface>hardware_interface/JointStateInterface</hardwareInterface>-->
      <hardwareInterface>hardware_interface/EffortJointInterface</hardwareInterface>
    </joint>
    <actuator name="hand_thumb_motor">
      <mechanicalReduction>0.162993578547</mechanicalReduction>
    </actuator>
  </transmission>
  <!--Abductor-->
  <transmission name="hand_index_abd_trans">
    <type>hey5_transmissions/Hey5Reducer</type>
    <joint name="hand_index_abd_joint">
      <saturationLower>0.0</saturationLower>
      <saturationUpper>0.523598775598</saturationUpper>
      <!--<hardwareInterface>hardware_interface/JointStateInterface</hardwareInterface>-->
      <hardwareInterface>hardware_interface/EffortJointInterface</hardwareInterface>
    </joint>
    <actuator name="hand_index_motor">
      <mechanicalReduction>0.49866550057</mechanicalReduction>
    </actuator>
  </transmission>
  <!--First flexor-->
  <transmission name="hand_index_virtual_1_trans">
    <type>hey5_transmissions/Hey5Reducer</type>
    <joint name="hand_index_virtual_1_joint">
      <saturationLower>0.0</saturationLower>
      <deadBandUpper>0.7</deadBandUpper>
      <!--<hardwareInterface>hardware_interface/JointStateInterface</hardwareInterface>-->
      <hardwareInterface>hardware_interface/EffortJointInterface</hardwareInterface>
    </joint>
    <actuator name="hand_index_motor">
      <mechanicalReduction>0.102888610798</mechanicalReduction>
    </actuator>
  </transmission>
  <transmission name="hand_index_flex_1_trans">
    <type>hey5_transmissions/Hey5Reducer</type>
    <joint name="hand_index_flex_1_joint">
      <saturationLower>0.0</saturationLower>
      <deadBandUpper>0.7</deadBandUpper>
      <!--<hardwareInterface>hardware_interface/JointStateInterface</hardwareInterface>-->
      <hardwareInterface>hardware_interface/EffortJointInterface</hardwareInterface>
    </joint>
    <actuator name="hand_index_motor">
      <mechanicalReduction>0.102888610798</mechanicalReduction>
    </actuator>
  </transmission>
  <!--Second flexor-->
  <transmission name="hand_index_virtual_2_trans">
    <type>hey5_transmissions/Hey5Reducer</type>
    <joint name="hand_index_virtual_2_joint">
      <saturationLower>0.0</saturationLower>
      <deadBandUpper>0.7</deadBandUpper>
      <!--<hardwareInterface>hardware_interface/JointStateInterface</hardwareInterface>-->
      <hardwareInterface>hardware_interface/EffortJointInterface</hardwareInterface>
    </joint>
    <actuator name="hand_index_motor">
      <mechanicalReduction>0.102888610798</mechanicalReduction>
    </actuator>
  </transmission>
  <transmission name="hand_index_flex_2_trans">
    <type>hey5_transmissions/Hey5Reducer</type>
    <joint name="hand_index_flex_2_joint">
      <saturationLower>0.0</saturationLower>
      <deadBandUpper>0.7</deadBandUpper>
      <!--<hardwareInterface>hardware_interface/JointStateInterface</hardwareInterface>-->
      <hardwareInterface>hardware_interface/EffortJointInterface</hardwareInterface>
    </joint>
    <actuator name="hand_index_motor">
      <mechanicalReduction>0.102888610798</mechanicalReduction>
    </actuator>
  </transmission>
  <!--Third flexor-->
  <transmission name="hand_index_virtual_3_trans">
    <type>hey5_transmissions/Hey5Reducer</type>
    <joint name="hand_index_virtual_3_joint">
      <saturationLower>0.0</saturationLower>
      <deadBandUpper>0.7</deadBandUpper>
      <!--<hardwareInterface>hardware_interface/JointStateInterface</hardwareInterface>-->
      <hardwareInterface>hardware_interface/EffortJointInterface</hardwareInterface>
    </joint>
    <actuator name="hand_index_motor">
      <mechanicalReduction>0.102888610798</mechanicalReduction>
    </actuator>
  </transmission>
  <transmission name="hand_index_flex_3_trans">
    <type>hey5_transmissions/Hey5Reducer</type>
    <joint name="hand_index_flex_3_joint">
      <saturationLower>0.0</saturationLower>
      <deadBandUpper>0.7</deadBandUpper>
      <!--<hardwareInterface>hardware_interface/JointStateInterface</hardwareInterface>-->
      <hardwareInterface>hardware_interface/EffortJointInterface</hardwareInterface>
    </joint>
    <actuator name="hand_index_motor">
      <mechanicalReduction>0.102888610798</mechanicalReduction>
    </actuator>
  </transmission>
  <!--Abductor-->
  <transmission name="hand_middle_abd_trans">
    <type>hey5_transmissions/Hey5Reducer</type>
    <joint name="hand_middle_abd_joint">
      <saturationLower>0.0</saturationLower>
      <saturationUpper>0.0</saturationUpper>
      <!--<hardwareInterface>hardware_interface/JointStateInterface</hardwareInterface>-->
      <hardwareInterface>hardware_interface/EffortJointInterface</hardwareInterface>
    </joint>
    <actuator name="hand_mrl_motor">
      <mechanicalReduction>1.0</mechanicalReduction>
    </actuator>
  </transmission>
  <!--First flexor-->
  <transmission name="hand_middle_virtual_1_trans">
    <type>hey5_transmissions/Hey5Reducer</type>
    <joint name="hand_middle_virtual_1_joint">
      <saturationLower>0.0</saturationLower>
      <deadBandUpper>0.0</deadBandUpper>
      <!--<hardwareInterface>hardware_interface/JointStateInterface</hardwareInterface>-->
      <hardwareInterface>hardware_interface/EffortJointInterface</hardwareInterface>
    </joint>
    <actuator name="hand_mrl_motor">
      <mechanicalReduction>0.0679245283019</mechanicalReduction>
    </actuator>
  </transmission>
  <transmission name="hand_middle_flex_1_trans">
    <type>hey5_transmissions/Hey5Reducer</type>
    <joint name="hand_middle_flex_1_joint">
      <saturationLower>0.0</saturationLower>
      <deadBandUpper>0.0</deadBandUpper>
      <!--<hardwareInterface>hardware_interface/JointStateInterface</hardwareInterface>-->
      <hardwareInterface>hardware_interface/EffortJointInterface</hardwareInterface>
    </joint>
    <actuator name="hand_mrl_motor">
      <mechanicalReduction>0.0679245283019</mechanicalReduction>
    </actuator>
  </transmission>
  <!--Second flexor-->
  <transmission name="hand_middle_virtual_2_trans">
    <type>hey5_transmissions/Hey5Reducer</type>
    <joint name="hand_middle_virtual_2_joint">
      <saturationLower>0.0</saturationLower>
      <deadBandUpper>0.0</deadBandUpper>
      <!--<hardwareInterface>hardware_interface/JointStateInterface</hardwareInterface>-->
      <hardwareInterface>hardware_interface/EffortJointInterface</hardwareInterface>
    </joint>
    <actuator name="hand_mrl_motor">
      <mechanicalReduction>0.0679245283019</mechanicalReduction>
    </actuator>
  </transmission>
  <transmission name="hand_middle_flex_2_trans">
    <type>hey5_transmissions/Hey5Reducer</type>
    <joint name="hand_middle_flex_2_joint">
      <saturationLower>0.0</saturationLower>
      <deadBandUpper>0.0</deadBandUpper>
      <!--<hardwareInterface>hardware_interface/JointStateInterface</hardwareInterface>-->
      <hardwareInterface>hardware_interface/EffortJointInterface</hardwareInterface>
    </joint>
    <actuator name="hand_mrl_motor">
      <mechanicalReduction>0.0679245283019</mechanicalReduction>
    </actuator>
  </transmission>
  <!--Third flexor-->
  <transmission name="hand_middle_virtual_3_trans">
    <type>hey5_transmissions/Hey5Reducer</type>
    <joint name="hand_middle_virtual_3_joint">
      <saturationLower>0.0</saturationLower>
      <deadBandUpper>0.0</deadBandUpper>
      <!--<hardwareInterface>hardware_interface/JointStateInterface</hardwareInterface>-->
      <hardwareInterface>hardware_interface/EffortJointInterface</hardwareInterface>
    </joint>
    <actuator name="hand_mrl_motor">
      <mechanicalReduction>0.0679245283019</mechanicalReduction>
    </actuator>
  </transmission>
  <transmission name="hand_middle_flex_3_trans">
    <type>hey5_transmissions/Hey5Reducer</type>
    <joint name="hand_middle_flex_3_joint">
      <saturationLower>0.0</saturationLower>
      <deadBandUpper>0.0</deadBandUpper>
      <!--<hardwareInterface>hardware_interface/JointStateInterface</hardwareInterface>-->
      <hardwareInterface>hardware_interface/EffortJointInterface</hardwareInterface>
    </joint>
    <actuator name="hand_mrl_motor">
      <mechanicalReduction>0.0679245283019</mechanicalReduction>
    </actuator>
  </transmission>
  <!--Abductor-->
  <transmission name="hand_ring_abd_trans">
    <type>hey5_transmissions/Hey5Reducer</type>
    <joint name="hand_ring_abd_joint">
      <saturationLower>-0.261799387799</saturationLower>
      <saturationUpper>0.0</saturationUpper>
      <!--<hardwareInterface>hardware_interface/JointStateInterface</hardwareInterface>-->
      <hardwareInterface>hardware_interface/EffortJointInterface</hardwareInterface>
    </joint>
    <actuator name="hand_mrl_motor">
      <mechanicalReduction>-0.232710566933</mechanicalReduction>
    </actuator>
  </transmission>
  <!--First flexor-->
  <transmission name="hand_ring_virtual_1_trans">
    <type>hey5_transmissions/Hey5Reducer</type>
    <joint name="hand_ring_virtual_1_joint">
      <saturationLower>0.0</saturationLower>
      <deadBandUpper>0.75</deadBandUpper>
      <!--<hardwareInterface>hardware_interface/JointStateInterface</hardwareInterface>-->
      <hardwareInterface>hardware_interface/EffortJointInterface</hardwareInterface>
    </joint>
    <actuator name="hand_mrl_motor">
      <mechanicalReduction>0.0739176962651</mechanicalReduction>
    </actuator>
  </transmission>
  <transmission name="hand_ring_flex_1_trans">
    <type>hey5_transmissions/Hey5Reducer</type>
    <joint name="hand_ring_flex_1_joint">
      <saturationLower>0.0</saturationLower>
      <deadBandUpper>0.75</deadBandUpper>
      <!--<hardwareInterface>hardware_interface/JointStateInterface</hardwareInterface>-->
      <hardwareInterface>hardware_interface/EffortJointInterface</hardwareInterface>
    </joint>
    <actuator name="hand_mrl_motor">
      <mechanicalReduction>0.0739176962651</mechanicalReduction>
    </actuator>
  </transmission>
  <!--Second flexor-->
  <transmission name="hand_ring_virtual_2_trans">
    <type>hey5_transmissions/Hey5Reducer</type>
    <joint name="hand_ring_virtual_2_joint">
      <saturationLower>0.0</saturationLower>
      <deadBandUpper>0.75</deadBandUpper>
      <!--<hardwareInterface>hardware_interface/JointStateInterface</hardwareInterface>-->
      <hardwareInterface>hardware_interface/EffortJointInterface</hardwareInterface>
    </joint>
    <actuator name="hand_mrl_motor">
      <mechanicalReduction>0.0739176962651</mechanicalReduction>
    </actuator>
  </transmission>
  <transmission name="hand_ring_flex_2_trans">
    <type>hey5_transmissions/Hey5Reducer</type>
    <joint name="hand_ring_flex_2_joint">
      <saturationLower>0.0</saturationLower>
      <deadBandUpper>0.75</deadBandUpper>
      <!--<hardwareInterface>hardware_interface/JointStateInterface</hardwareInterface>-->
      <hardwareInterface>hardware_interface/EffortJointInterface</hardwareInterface>
    </joint>
    <actuator name="hand_mrl_motor">
      <mechanicalReduction>0.0739176962651</mechanicalReduction>
    </actuator>
  </transmission>
  <!--Third flexor-->
  <transmission name="hand_ring_virtual_3_trans">
    <type>hey5_transmissions/Hey5Reducer</type>
    <joint name="hand_ring_virtual_3_joint">
      <saturationLower>0.0</saturationLower>
      <deadBandUpper>0.75</deadBandUpper>
      <!--<hardwareInterface>hardware_interface/JointStateInterface</hardwareInterface>-->
      <hardwareInterface>hardware_interface/EffortJointInterface</hardwareInterface>
    </joint>
    <actuator name="hand_mrl_motor">
      <mechanicalReduction>0.0739176962651</mechanicalReduction>
    </actuator>
  </transmission>
  <transmission name="hand_ring_flex_3_trans">
    <type>hey5_transmissions/Hey5Reducer</type>
    <joint name="hand_ring_flex_3_joint">
      <saturationLower>0.0</saturationLower>
      <deadBandUpper>0.75</deadBandUpper>
      <!--<hardwareInterface>hardware_interface/JointStateInterface</hardwareInterface>-->
      <hardwareInterface>hardware_interface/EffortJointInterface</hardwareInterface>
    </joint>
    <actuator name="hand_mrl_motor">
      <mechanicalReduction>0.0739176962651</mechanicalReduction>
    </actuator>
  </transmission>
  <!--Abductor-->
  <transmission name="hand_little_abd_trans">
    <type>hey5_transmissions/Hey5Reducer</type>
    <joint name="hand_little_abd_joint">
      <saturationLower>-0.523598775598</saturationLower>
      <saturationUpper>0.0</saturationUpper>
      <!--<hardwareInterface>hardware_interface/JointStateInterface</hardwareInterface>-->
      <hardwareInterface>hardware_interface/EffortJointInterface</hardwareInterface>
    </joint>
    <actuator name="hand_mrl_motor">
      <mechanicalReduction>-0.465421133865</mechanicalReduction>
    </actuator>
  </transmission>
  <!--First flexor-->
  <transmission name="hand_little_virtual_1_trans">
    <type>hey5_transmissions/Hey5Reducer</type>
    <joint name="hand_little_virtual_1_joint">
      <saturationLower>0.0</saturationLower>
      <deadBandUpper>0.75</deadBandUpper>
      <!--<hardwareInterface>hardware_interface/JointStateInterface</hardwareInterface>-->
      <hardwareInterface>hardware_interface/EffortJointInterface</hardwareInterface>
    </joint>
    <actuator name="hand_mrl_motor">
      <mechanicalReduction>0.0739176962651</mechanicalReduction>
    </actuator>
  </transmission>
  <transmission name="hand_little_flex_1_trans">
    <type>hey5_transmissions/Hey5Reducer</type>
    <joint name="hand_little_flex_1_joint">
      <saturationLower>0.0</saturationLower>
      <deadBandUpper>0.75</deadBandUpper>
      <!--<hardwareInterface>hardware_interface/JointStateInterface</hardwareInterface>-->
      <hardwareInterface>hardware_interface/EffortJointInterface</hardwareInterface>
    </joint>
    <actuator name="hand_mrl_motor">
      <mechanicalReduction>0.0739176962651</mechanicalReduction>
    </actuator>
  </transmission>
  <!--Second flexor-->
  <transmission name="hand_little_virtual_2_trans">
    <type>hey5_transmissions/Hey5Reducer</type>
    <joint name="hand_little_virtual_2_joint">
      <saturationLower>0.0</saturationLower>
      <deadBandUpper>0.75</deadBandUpper>
      <!--<hardwareInterface>hardware_interface/JointStateInterface</hardwareInterface>-->
      <hardwareInterface>hardware_interface/EffortJointInterface</hardwareInterface>
    </joint>
    <actuator name="hand_mrl_motor">
      <mechanicalReduction>0.0739176962651</mechanicalReduction>
    </actuator>
  </transmission>
  <transmission name="hand_little_flex_2_trans">
    <type>hey5_transmissions/Hey5Reducer</type>
    <joint name="hand_little_flex_2_joint">
      <saturationLower>0.0</saturationLower>
      <deadBandUpper>0.75</deadBandUpper>
      <!--<hardwareInterface>hardware_interface/JointStateInterface</hardwareInterface>-->
      <hardwareInterface>hardware_interface/EffortJointInterface</hardwareInterface>
    </joint>
    <actuator name="hand_mrl_motor">
      <mechanicalReduction>0.0739176962651</mechanicalReduction>
    </actuator>
  </transmission>
  <!--Third flexor-->
  <transmission name="hand_little_virtual_3_trans">
    <type>hey5_transmissions/Hey5Reducer</type>
    <joint name="hand_little_virtual_3_joint">
      <saturationLower>0.0</saturationLower>
      <deadBandUpper>0.75</deadBandUpper>
      <!--<hardwareInterface>hardware_interface/JointStateInterface</hardwareInterface>-->
      <hardwareInterface>hardware_interface/EffortJointInterface</hardwareInterface>
    </joint>
    <actuator name="hand_mrl_motor">
      <mechanicalReduction>0.0739176962651</mechanicalReduction>
    </actuator>
  </transmission>
  <transmission name="hand_little_flex_3_trans">
    <type>hey5_transmissions/Hey5Reducer</type>
    <joint name="hand_little_flex_3_joint">
      <saturationLower>0.0</saturationLower>
      <deadBandUpper>0.75</deadBandUpper>
      <!--<hardwareInterface>hardware_interface/JointStateInterface</hardwareInterface>-->
      <hardwareInterface>hardware_interface/EffortJointInterface</hardwareInterface>
    </joint>
    <actuator name="hand_mrl_motor">
      <mechanicalReduction>0.0739176962651</mechanicalReduction>
    </actuator>
  </transmission>
  <link name="hand_grasping_frame"/>
  <joint name="hand_grasping_fixed_joint" type="fixed">
    <parent link="hand_palm_link"/>
    <child link="hand_grasping_frame"/>
    <axis xyz="0 0 1"/>
    <origin rpy="0 0 0" xyz="0.13 0.02 0"/>
  </joint>
  <gazebo>
    <plugin filename="libgazebo_underactuated_finger.so" name="gazebo_hand_thumb">
      <actuatedJoint>hand_thumb_joint</actuatedJoint>
      <virtualJoint>
        <name>hand_thumb_abd_joint</name>
        <scale_factor>2.0</scale_factor>
      </virtualJoint>
      <virtualJoint>
        <name>hand_thumb_flex_1_joint</name>
        <scale_factor>2.5</scale_factor>
      </virtualJoint>
      <virtualJoint>
        <name>hand_thumb_virtual_1_joint</name>
        <scale_factor>3.0</scale_factor>
      </virtualJoint>
      <virtualJoint>
        <name>hand_thumb_flex_2_joint</name>
        <scale_factor>3.5</scale_factor>
      </virtualJoint>
      <virtualJoint>
        <name>hand_thumb_virtual_2_joint</name>
        <scale_factor>3.0</scale_factor>
      </virtualJoint>
    </plugin>
    <plugin filename="libgazebo_underactuated_finger.so" name="gazebo_hand_index">
      <actuatedJoint>hand_index_joint</actuatedJoint>
      <virtualJoint>
        <name>hand_index_abd_joint</name>
        <scale_factor>5.0</scale_factor>
      </virtualJoint>
      <virtualJoint>
        <name>hand_index_flex_1_joint</name>
        <scale_factor>2.5</scale_factor>
      </virtualJoint>
      <virtualJoint>
        <name>hand_index_virtual_1_joint</name>
        <scale_factor>3.0</scale_factor>
      </virtualJoint>
      <virtualJoint>
        <name>hand_index_flex_2_joint</name>
        <scale_factor>3.5</scale_factor>
      </virtualJoint>
      <virtualJoint>
        <name>hand_index_virtual_2_joint</name>
        <scale_factor>3.5</scale_factor>
      </virtualJoint>
      <virtualJoint>
        <name>hand_index_flex_3_joint</name>
        <scale_factor>4.0</scale_factor>
      </virtualJoint>
    </plugin>
    <plugin filename="libgazebo_underactuated_finger.so" name="gazebo_hand_middle">
      <actuatedJoint>hand_mrl_joint</actuatedJoint>
      <virtualJoint>
        <name>hand_middle_flex_1_joint</name>
        <scale_factor>2.5</scale_factor>
      </virtualJoint>
      <virtualJoint>
        <name>hand_middle_virtual_1_joint</name>
        <scale_factor>3.0</scale_factor>
      </virtualJoint>
      <virtualJoint>
        <name>hand_middle_flex_2_joint</name>
        <scale_factor>3.5</scale_factor>
      </virtualJoint>
      <virtualJoint>
        <name>hand_middle_virtual_2_joint</name>
        <scale_factor>3.5</scale_factor>
      </virtualJoint>
      <virtualJoint>
        <name>hand_middle_flex_3_joint</name>
        <scale_factor>4.0</scale_factor>
      </virtualJoint>
    </plugin>
    <plugin filename="libgazebo_underactuated_finger.so" name="gazebo_hand_ring">
      <actuatedJoint>hand_mrl_joint</actuatedJoint>
      <virtualJoint>
        <name>hand_ring_flex_1_joint</name>
        <scale_factor>2.5</scale_factor>
      </virtualJoint>
      <virtualJoint>
        <name>hand_ring_virtual_1_joint</name>
        <scale_factor>3.0</scale_factor>
      </virtualJoint>
      <virtualJoint>
        <name>hand_ring_flex_2_joint</name>
        <scale_factor>3.5</scale_factor>
      </virtualJoint>
      <virtualJoint>
        <name>hand_ring_virtual_2_joint</name>
        <scale_factor>3.5</scale_factor>
      </virtualJoint>
      <virtualJoint>
        <name>hand_ring_flex_3_joint</name>
        <scale_factor>4.0</scale_factor>
      </virtualJoint>
    </plugin>
    <plugin filename="libgazebo_underactuated_finger.so" name="gazebo_hand_little">
      <actuatedJoint>hand_mrl_joint</actuatedJoint>
      <virtualJoint>
        <name>hand_little_flex_1_joint</name>
        <scale_factor>2.5</scale_factor>
      </virtualJoint>
      <virtualJoint>
        <name>hand_little_virtual_1_joint</name>
        <scale_factor>3.0</scale_factor>
      </virtualJoint>
      <virtualJoint>
        <name>hand_little_flex_2_joint</name>
        <scale_factor>3.5</scale_factor>
      </virtualJoint>
      <virtualJoint>
        <name>hand_little_virtual_2_joint</name>
        <scale_factor>3.5</scale_factor>
      </virtualJoint>
      <virtualJoint>
        <name>hand_little_flex_3_joint</name>
        <scale_factor>4.0</scale_factor>
      </virtualJoint>
    </plugin>
  </gazebo>
  <joint name="hand_safety_box_joint" type="fixed">
    <parent link="fore_link"/>
    <child link="hand_safety_box"/>
    <origin rpy="-1.57 0 0" xyz="0.5 0 0"/>
    <!--<origin xyz="0.1 0.02 ${reflect * 0.02}" rpy="0 0 0"/>-->
  </joint>
  <link name="hand_safety_box">
    <inertial>
      <origin rpy="0 0 0" xyz="0 0 0"/>
      <mass value="0.0001"/>
      <inertia ixx="0.0001" ixy="0" ixz="0" iyy="0.0001" iyz="0" izz="0.0001"/>
    </inertial>
    <!--
      <visual>
        <origin xyz="0 0 0" rpy="0 0 0" />
        <geometry>
          <box size="0.2 0.115 0.18" />
        </geometry>
      </visual>
      -->
    <collision>
      <origin rpy="0 0 0" xyz="0 0 0"/>
      <geometry>
        <box size="0.2 0.115 0.18"/>
      </geometry>
    </collision>
  </link>
  <!--Arm Stand-->
  <link name="world"/>
  <joint name="fixed" type="fixed">
    <parent link="world"/>
    <child link="base_link"/>
  </joint>
  <!-- Base Link -->
  <link name="base_link">
    <visual>
      <origin rpy="0 0 0" xyz="0 0 0.5"/>
      <geometry>
        <box size="0.1 0.1 1"/>
      </geometry>
      <material name="white"/>
    </visual>
    <collision>
      <origin rpy="0 0 0" xyz="0 0 0.5"/>
      <geometry>
        <box size="0.1 0.1 1"/>
      </geometry>
    </collision>
    <inertial>
      <origin rpy="0 0 0" xyz="0 0 0.5"/>
      <mass value="1"/>
      <inertia ixx="0.0841666666667" ixy="0.0" ixz="0.0" iyy="0.0841666666667" iyz="0.0" izz="0.00166666666667"/>
    </inertial>
  </link>
  <!-- Joint between Base Link and Middle Link -->
  <joint name="joint_base_mid" type="revolute">
    <parent link="base_link"/>
    <child link="mid_link"/>
    <origin rpy="0 0 0" xyz="0 0.1 0.95"/>
    <axis xyz="0 1 0"/>
    <dynamics damping="0.7" friction="0"/>
    <limit effort="1000.0" lower="-3.14" upper="3.14" velocity="0.5"/>
  </joint>
  <!-- Middle Link -->
  <link name="mid_link">
    <visual>
      <origin rpy="0 0 0" xyz="0 0 0.2"/>
      <geometry>
        <box size="0.1 0.1 0.5"/>
      </geometry>
      <material name="green"/>
    </visual>
    <collision>
      <origin rpy="0 0 0" xyz="0 0 0.2"/>
      <geometry>
        <box size="0.1 0.1 0.5"/>
      </geometry>
    </collision>
    <inertial>
      <origin rpy="0 0 0" xyz="0 0 0.2"/>
      <mass value="1"/>
      <inertia ixx="0.0216666666667" ixy="0.0" ixz="0.0" iyy="0.0216666666667" iyz="0.0" izz="0.00166666666667"/>
    </inertial>
  </link>
  <!-- Joint between Middle Link and Top Link -->
  <joint name="joint_mid_top" type="revolute">
    <parent link="mid_link"/>
    <child link="top_link"/>
    <origin rpy="0 0 0" xyz="0 0 0.5"/>
    <axis xyz="0 0 1"/>
    <dynamics damping="0.7" friction="0"/>
    <limit effort="1000.0" lower="-3.14" upper="3.14" velocity="0.5"/>
  </joint>
  <!-- Top Link -->
  <link name="top_link">
    <visual>
      <origin rpy="0 0 0" xyz="0.2 0 0"/>
      <geometry>
        <box size="0.5 0.1 0.1"/>
      </geometry>
      <material name="red"/>
    </visual>
    <collision>
      <origin rpy="0 0 0" xyz="0.2 0 0"/>
      <geometry>
        <box size="0.5 0.1 0.1"/>
      </geometry>
    </collision>
    <inertial>
      <origin rpy="0 0 0" xyz="0.2 0 0"/>
      <mass value="1"/>
      <inertia ixx="0.0" ixy="0.0" ixz="0.0" iyy="0.020833325" iyz="0.0" izz="0.020833325"/>
    </inertial>
  </link>
  <!-- Joint between Top Link and Forearm Link -->
  <joint name="joint_top_fore" type="revolute">
    <parent link="top_link"/>
    <child link="fore_link"/>
    <origin rpy="0 0 0" xyz="0.45 0 0"/>
    <axis xyz="1 0 0"/>
    <dynamics damping="0.7" friction="0"/>
    <limit effort="1000.0" lower="-3.14" upper="3.14" velocity="0.5"/>
  </joint>
  <link name="fore_link">
    <visual>
      <origin rpy="0 0 0" xyz="0.25 0 0"/>
      <geometry>
        <box size="0.5 0.1 0.1"/>
      </geometry>
      <material name="blue"/>
    </visual>
    <collision>
      <origin rpy="0 0 0" xyz="0.25 0 0"/>
      <geometry>
        <box size="0.5 0.1 0.1"/>
      </geometry>
    </collision>
    <inertial>
      <origin rpy="0 0 0" xyz="0.25 0 0"/>
      <mass value="1"/>
      <inertia ixx="0.0" ixy="0.0" ixz="0.0" iyy="0.020833325" iyz="0.0" izz="0.020833325"/>
    </inertial>
  </link>
  <joint name="camera_joint" type="fixed">
    <origin rpy="0 0 0" xyz="0.45 0 0"/>
    <parent link="fore_link"/>
    <child link="camera_link"/>
    <dynamics damping="0.7" friction="0"/>
  </joint>
  <!--Camera Link-->
  <link name="camera_link">
    <collision>
      <origin rpy="0 0 0" xyz="0 0 0.075"/>
      <geometry>
        <box size="0.05 0.05 0.05"/>
      </geometry>
    </collision>
    <visual>
      <origin rpy="0 0 0" xyz="0 0 0.075"/>
      <geometry>
        <box size="0.05 0.05 0.05"/>
      </geometry>
      <material name="white"/>
    </visual>
    <inertial>
      <mass value="1e-5"/>
      <origin rpy="0 0 0" xyz="0 0 0"/>
      <inertia ixx="1e-6" ixy="0" ixz="0" iyy="1e-6" iyz="0" izz="1e-6"/>
    </inertial>
  </link>
  <!--Transmission-->
  <transmission name="trans_base_mid">
    <type>transmission_interface/SimpleTransmission</type>
    <joint name="joint_base_mid">
      <hardwareInterface>hardware_interface/EffortJointInterface</hardwareInterface>
    </joint>
    <actuator name="motor_base_mid">
      <hardwareInterface>hardware_interface/EffortJointInterface</hardwareInterface>
      <mechanicalReduction>1</mechanicalReduction>
    </actuator>
  </transmission>
  <transmission name="trans_mid_top">
    <type>transmission_interface/SimpleTransmission</type>
    <joint name="joint_mid_top">
      <hardwareInterface>hardware_interface/EffortJointInterface</hardwareInterface>
    </joint>
    <actuator name="motor_mid_top">
      <hardwareInterface>hardware_interface/EffortJointInterface</hardwareInterface>
      <mechanicalReduction>1</mechanicalReduction>
    </actuator>
  </transmission>
  <transmission name="trans_top_fore">
    <type>transmission_interface/SimpleTransmission</type>
    <joint name="joint_top_fore">
      <hardwareInterface>hardware_interface/EffortJointInterface</hardwareInterface>
    </joint>
    <actuator name="motor_top_fore">
      <hardwareInterface>hardware_interface/EffortJointInterface</hardwareInterface>
      <mechanicalReduction>1</mechanicalReduction>
    </actuator>
  </transmission>
  <!-- <joint name="hand_joint" type="revolute">
    <parent link="top_link"/>
    <child link="left_gripper"/>
    <origin xyz="0 0 ${height2 - axle_offset}" rpy="0 -1.57 0"/>
    <axis xyz="0 0 1"/>
    <limit effort="30.0" lower="-0.548" upper="0.0" velocity="0.1"/>
  </joint> -->
</robot>
<!--
  This XML code defines a robot arm which has three links that are
0.1 meters deep and wide. The base_link is 2 meters tall, and the mid_link and top_link are both 1 meter tall. The origin of the base_link is at (0, 0, 1).
The reference frame of the box is 1 meter in the z direction above the reference frame of the link. This base_link is identified as the URDF root link and is the beginning of the kinematic chain for the
arm. The collision elements of each match their visual elements. Each inertial element indicates that each link weighs 1 kilogram and has the same basic inertia matrix values.

 The dynamics damping coefficient is set to 0.7 Nms/rad. This damping
is the amount of opposing force to any joint velocity, used to slow down the moving arms to a rest position. The <limit> tag is required for revolute joints. The limit effort is set to 1000.0 N-m for the maximum joint effort that can be commanded. The joint velocity is limited to a magnitude of 0.5 rad/s, with a damping effort applied when the joint is commanded beyond this limit. The upper and lower limits of the joint are set to pi radians and -pi radians, respectively.
-->

