<sdf version='1.6'>
  <model name='arm_stand'>
    <link name='base_link'>
      <pose frame=''>0 0 0 0 -0 0</pose>
      <inertial>
        <pose frame=''>0 0 0.5 0 -0 0</pose>
        <mass>1</mass>
        <inertia>
          <ixx>0.0841667</ixx>
          <ixy>0</ixy>
          <ixz>0</ixz>
          <iyy>0.0841667</iyy>
          <iyz>0</iyz>
          <izz>0.00166667</izz>
        </inertia>
      </inertial>
      <collision name='base_link_collision'>
        <pose frame=''>0 0 0.5 0 -0 0</pose>
        <geometry>
          <box>
            <size>0.1 0.1 1</size>
          </box>
        </geometry>
        <surface>
          <contact>
            <ode/>
          </contact>
          <friction>
            <ode/>
          </friction>
        </surface>
      </collision>
      <visual name='base_link_visual'>
        <pose frame=''>0 0 0.5 0 -0 0</pose>
        <geometry>
          <box>
            <size>0.1 0.1 1</size>
          </box>
        </geometry>
        <material>
          <script>
            <name>Gazebo/White</name>
            <uri>file://media/materials/scripts/gazebo.material</uri>
          </script>
        </material>
      </visual>
      <gravity>1</gravity>
      <velocity_decay/>
    </link>
    <joint name='fixed' type='fixed'>
      <child>base_link</child>
      <parent>world</parent>
    </joint>
    <link name='mid_link'>
      <pose frame=''>0 0.1 0.95 0 -0 0</pose>
      <inertial>
        <pose frame=''>0 0 0.2 0 -0 0</pose>
        <mass>1</mass>
        <inertia>
          <ixx>0.0216667</ixx>
          <ixy>0</ixy>
          <ixz>0</ixz>
          <iyy>0.0216667</iyy>
          <iyz>0</iyz>
          <izz>0.00166667</izz>
        </inertia>
      </inertial>
      <collision name='mid_link_collision'>
        <pose frame=''>0 0 0.2 0 -0 0</pose>
        <geometry>
          <box>
            <size>0.1 0.1 0.5</size>
          </box>
        </geometry>
        <surface>
          <contact>
            <ode/>
          </contact>
          <friction>
            <ode>
              <mu>0.2</mu>
              <mu2>0.2</mu2>
            </ode>
          </friction>
        </surface>
      </collision>
      <visual name='mid_link_visual'>
        <pose frame=''>0 0 0.2 0 -0 0</pose>
        <geometry>
          <box>
            <size>0.1 0.1 0.5</size>
          </box>
        </geometry>
        <material>
          <script>
            <name>Gazebo/Green</name>
            <uri>file://media/materials/scripts/gazebo.material</uri>
          </script>
        </material>
      </visual>
      <gravity>0</gravity>
      <velocity_decay/>
    </link>
    <joint name='joint_base_mid' type='revolute'>
      <child>mid_link</child>
      <parent>base_link</parent>
      <axis>
        <xyz>0 1 0</xyz>
        <limit>
          <lower>-3.14</lower>
          <upper>3.14</upper>
          <effort>1000</effort>
          <velocity>0.5</velocity>
        </limit>
        <dynamics>
          <damping>0.7</damping>
          <friction>0</friction>
          <spring_reference>0</spring_reference>
          <spring_stiffness>0</spring_stiffness>
        </dynamics>
        <use_parent_model_frame>1</use_parent_model_frame>
      </axis>
    </joint>
    <link name='top_link'>
      <pose frame=''>0 0.1 1.45 0 -0 0</pose>
      <inertial>
        <pose frame=''>0.2 0 0 0 -0 0</pose>
        <mass>1</mass>
        <inertia>
          <ixx>0</ixx>
          <ixy>0</ixy>
          <ixz>0</ixz>
          <iyy>0.0208333</iyy>
          <iyz>0</iyz>
          <izz>0.0208333</izz>
        </inertia>
      </inertial>
      <collision name='top_link_collision'>
        <pose frame=''>0.2 0 0 0 -0 0</pose>
        <geometry>
          <box>
            <size>0.5 0.1 0.1</size>
          </box>
        </geometry>
        <surface>
          <contact>
            <ode/>
          </contact>
          <friction>
            <ode>
              <mu>0.2</mu>
              <mu2>0.2</mu2>
            </ode>
          </friction>
        </surface>
      </collision>
      <visual name='top_link_visual'>
        <pose frame=''>0.2 0 0 0 -0 0</pose>
        <geometry>
          <box>
            <size>0.5 0.1 0.1</size>
          </box>
        </geometry>
        <material>
          <script>
            <name>Gazebo/Red</name>
            <uri>file://media/materials/scripts/gazebo.material</uri>
          </script>
        </material>
      </visual>
      <gravity>0</gravity>
      <velocity_decay/>
    </link>
    <joint name='joint_mid_top' type='revolute'>
      <child>top_link</child>
      <parent>mid_link</parent>
      <axis>
        <xyz>0 0 1</xyz>
        <limit>
          <lower>-3.14</lower>
          <upper>3.14</upper>
          <effort>1000</effort>
          <velocity>0.5</velocity>
        </limit>
        <dynamics>
          <damping>0.7</damping>
          <friction>0</friction>
          <spring_reference>0</spring_reference>
          <spring_stiffness>0</spring_stiffness>
        </dynamics>
        <use_parent_model_frame>1</use_parent_model_frame>
      </axis>
    </joint>
    <link name='fore_link'>
      <pose frame=''>0.45 0.1 1.45 0 -0 0</pose>
      <inertial>
        <pose frame=''>0.339766 0.000599 0.000629 0 -0 0</pose>
        <mass>1.4002</mass>
        <inertia>
          <ixx>0.000417743</ixx>
          <ixy>-0.000172977</ixy>
          <ixz>-0.000202589</ixz>
          <iyy>0.0497939</iyy>
          <iyz>-9.06625e-06</iyz>
          <izz>0.0499499</izz>
        </inertia>
      </inertial>
      <collision name='fore_link_collision'>
        <pose frame=''>0.25 0 0 0 -0 0</pose>
        <geometry>
          <box>
            <size>0.5 0.1 0.1</size>
          </box>
        </geometry>
        <surface>
          <contact>
            <ode/>
          </contact>
          <friction>
            <ode>
              <mu>0.2</mu>
              <mu2>0.2</mu2>
            </ode>
          </friction>
        </surface>
      </collision>
      <collision name='fore_link_fixed_joint_lump__hand_palm_link_collision_1'>
        <pose frame=''>0.5 0 0 -1.57 0 0</pose>
        <geometry>
          <mesh>
            <scale>1 1 1</scale>
            <uri>model://hey5_description/meshes/palm_collision.stl</uri>
          </mesh>
        </geometry>
        <surface>
          <contact>
            <ode/>
          </contact>
          <friction>
            <ode/>
          </friction>
        </surface>
      </collision>
      <collision name='fore_link_fixed_joint_lump__hand_safety_box_collision_2'>
        <pose frame=''>0.5 0 0 -1.57 0 0</pose>
        <geometry>
          <box>
            <size>0.2 0.115 0.18</size>
          </box>
        </geometry>
        <surface>
          <contact>
            <ode/>
          </contact>
          <friction>
            <ode/>
          </friction>
        </surface>
      </collision>
      <visual name='fore_link_visual'>
        <pose frame=''>0.25 0 0 0 -0 0</pose>
        <geometry>
          <box>
            <size>0.5 0.1 0.1</size>
          </box>
        </geometry>
        <material>
          <script>
            <name>Gazebo/Blue</name>
            <uri>file://media/materials/scripts/gazebo.material</uri>
          </script>
        </material>
      </visual>
      <visual name='fore_link_fixed_joint_lump__hand_palm_link_visual_1'>
        <pose frame=''>0.5 0 0 -1.57 0 0</pose>
        <geometry>
          <mesh>
            <scale>1 1 1</scale>
            <uri>model://hey5_description/meshes/palm.stl</uri>
          </mesh>
        </geometry>
        <material>
          <script>
            <name>Gazebo/Black</name>
            <uri>file://media/materials/scripts/gazebo.material</uri>
          </script>
        </material>
      </visual>
      <velocity_decay/>
      <velocity_decay/>
      <velocity_decay/>
      <velocity_decay/>
      <gravity>0</gravity>
      <velocity_decay/>
    </link>
    <joint name='joint_top_fore' type='revolute'>
      <child>fore_link</child>
      <parent>top_link</parent>
      <axis>
        <xyz>1 0 0</xyz>
        <limit>
          <lower>-3.14</lower>
          <upper>3.14</upper>
          <effort>1000</effort>
          <velocity>0.5</velocity>
        </limit>
        <dynamics>
          <damping>0.7</damping>
          <friction>0</friction>
          <spring_reference>0</spring_reference>
          <spring_stiffness>0</spring_stiffness>
        </dynamics>
        <use_parent_model_frame>1</use_parent_model_frame>
      </axis>
    </joint>
    <link name='camera_link'>
      <pose frame=''>0.9 0.1 1.45 0 -0 0</pose>
      <inertial>
        <pose frame=''>0 0 0 0 -0 0</pose>
        <mass>1e-05</mass>
        <inertia>
          <ixx>1e-06</ixx>
          <ixy>0</ixy>
          <ixz>0</ixz>
          <iyy>1e-06</iyy>
          <iyz>0</iyz>
          <izz>1e-06</izz>
        </inertia>
      </inertial>
      <collision name='camera_link_collision'>
        <pose frame=''>0 0 0.075 0 -0 0</pose>
        <geometry>
          <box>
            <size>0.05 0.05 0.05</size>
          </box>
        </geometry>
        <surface>
          <contact>
            <ode/>
          </contact>
          <friction>
            <ode/>
          </friction>
        </surface>
      </collision>
      <visual name='camera_link_visual'>
        <pose frame=''>0 0 0.075 0 -0 0</pose>
        <geometry>
          <box>
            <size>0.05 0.05 0.05</size>
          </box>
        </geometry>
        <material>
          <script>
            <uri>__default__</uri>
            <name>__default__</name>
          </script>
        </material>
      </visual>
      <gravity>0</gravity>
      <velocity_decay/>
      <sensor name='camera1' type='camera'>
        <update_rate>30</update_rate>
        <camera name='camera1'>
          <horizontal_fov>1.39626</horizontal_fov>
          <image>
            <width>800</width>
            <height>800</height>
            <format>R8G8B8</format>
          </image>
          <clip>
            <near>0.02</near>
            <far>300</far>
          </clip>
          <noise>
            <type>gaussian</type>
            <mean>0</mean>
            <stddev>0.007</stddev>
          </noise>
        </camera>
        <plugin name='camera_controller' filename='libgazebo_ros_camera.so'>
          <alwaysOn>1</alwaysOn>
          <updateRate>0.0</updateRate>
          <cameraName>camera1</cameraName>
          <imageTopicName>image_raw</imageTopicName>
          <cameraInfoTopicName>camera_info</cameraInfoTopicName>
          <frameName>camera_link</frameName>
          <hackBaseline>0.07</hackBaseline>
          <distortionK1>0.0</distortionK1>
          <distortionK2>0.0</distortionK2>
          <distortionK3>0.0</distortionK3>
          <distortionT1>0.0</distortionT1>
          <distortionT2>0.0</distortionT2>
        </plugin>
      </sensor>
    </link>
    <joint name='camera_joint' type='fixed'>
      <child>camera_link</child>
      <parent>fore_link</parent>
      <axis>
        <dynamics>
          <spring_reference>0</spring_reference>
          <spring_stiffness>0</spring_stiffness>
        </dynamics>
        <use_parent_model_frame>1</use_parent_model_frame>
        <xyz>0 0 1</xyz>
        <limit>
          <lower>-1e+16</lower>
          <upper>1e+16</upper>
        </limit>
      </axis>
      <physics>
        <ode>
          <limit>
            <cfm>0</cfm>
            <erp>0.2</erp>
          </limit>
        </ode>
      </physics>
    </joint>
    <link name='hand_index_abd_link'>
      <pose frame=''>1.0765 0.126503 1.44582 -3.1409 -0.000398 0.523599</pose>
      <inertial>
        <pose frame=''>-0.0018 0 0.0028 0 -0 0</pose>
        <mass>0.018</mass>
        <inertia>
          <ixx>0.001</ixx>
          <ixy>0</ixy>
          <ixz>0</ixz>
          <iyy>0.001</iyy>
          <iyz>0</iyz>
          <izz>0.001</izz>
        </inertia>
      </inertial>
      <collision name='hand_index_abd_link_collision'>
        <pose frame=''>0 0 0 0 -0 0</pose>
        <geometry>
          <mesh>
            <scale>1 1 1</scale>
            <uri>model://hey5_description/meshes/finger_abd_collision.stl</uri>
          </mesh>
        </geometry>
        <surface>
          <contact>
            <ode/>
          </contact>
          <friction>
            <ode/>
          </friction>
        </surface>
      </collision>
      <visual name='hand_index_abd_link_visual'>
        <pose frame=''>0 0 0 0 -0 0</pose>
        <geometry>
          <mesh>
            <scale>1 1 1</scale>
            <uri>model://hey5_description/meshes/finger_abd_collision.stl</uri>
          </mesh>
        </geometry>
        <material>
          <script>
            <name>Gazebo/Black</name>
            <uri>file://media/materials/scripts/gazebo.material</uri>
          </script>
        </material>
      </visual>
      <gravity>1</gravity>
      <velocity_decay/>
    </link>
    <joint name='hand_index_abd_joint' type='revolute'>
      <child>hand_index_abd_link</child>
      <parent>fore_link</parent>
      <axis>
        <xyz>-0 0.000796 -1</xyz>
        <limit>
          <lower>-0.523599</lower>
          <upper>0.523599</upper>
          <effort>2</effort>
          <velocity>2</velocity>
        </limit>
        <dynamics>
          <damping>0.5</damping>
          <friction>0</friction>
          <spring_reference>0</spring_reference>
          <spring_stiffness>0</spring_stiffness>
        </dynamics>
        <use_parent_model_frame>1</use_parent_model_frame>
      </axis>
    </joint>
    <link name='hand_index_virtual_1_link'>
      <pose frame=''>1.08429 0.131003 1.44582 -1.57011 -0.000398 0.523599</pose>
      <inertial>
        <pose frame=''>0.0065 0 0 0 -0 0</pose>
        <mass>0.01</mass>
        <inertia>
          <ixx>0.001</ixx>
          <ixy>0</ixy>
          <ixz>0</ixz>
          <iyy>0.001</iyy>
          <iyz>0</iyz>
          <izz>0.001</izz>
        </inertia>
      </inertial>
      <collision name='hand_index_virtual_1_link_collision'>
        <pose frame=''>0 0 0 0 -0 0</pose>
        <geometry>
          <box>
            <size>0.013 0.002 0.012</size>
          </box>
        </geometry>
        <surface>
          <contact>
            <ode/>
          </contact>
          <friction>
            <ode/>
          </friction>
        </surface>
      </collision>
      <visual name='hand_index_virtual_1_link_visual'>
        <pose frame=''>0.0065 0 0 0 -0 0</pose>
        <geometry>
          <box>
            <size>0.013 0.002 0.012</size>
          </box>
        </geometry>
        <material>
          <script>
            <name>Gazebo/Black</name>
            <uri>file://media/materials/scripts/gazebo.material</uri>
          </script>
        </material>
      </visual>
      <gravity>1</gravity>
      <velocity_decay/>
    </link>
    <joint name='hand_index_virtual_1_joint' type='revolute'>
      <child>hand_index_virtual_1_link</child>
      <parent>hand_index_abd_link</parent>
      <axis>
        <xyz>-0.5 0.866025 0.00069</xyz>
        <limit>
          <lower>0</lower>
          <upper>0.785398</upper>
          <effort>2</effort>
          <velocity>2</velocity>
        </limit>
        <dynamics>
          <damping>0.5</damping>
          <friction>0</friction>
          <spring_reference>0</spring_reference>
          <spring_stiffness>0</spring_stiffness>
        </dynamics>
        <use_parent_model_frame>1</use_parent_model_frame>
      </axis>
    </joint>
    <link name='hand_index_flex_1_link'>
      <pose frame=''>1.09555 0.137503 1.44583 -1.57011 -0.000398 0.523599</pose>
      <inertial>
        <pose frame=''>0.0047 0.0031 0 0 -0 0</pose>
        <mass>0.009</mass>
        <inertia>
          <ixx>0.001</ixx>
          <ixy>0</ixy>
          <ixz>0</ixz>
          <iyy>0.001</iyy>
          <iyz>0</iyz>
          <izz>0.001</izz>
        </inertia>
      </inertial>
      <collision name='hand_index_flex_1_link_collision'>
        <pose frame=''>0 0 0 0 -0 0</pose>
        <geometry>
          <mesh>
            <scale>1 1 1</scale>
            <uri>model://hey5_description/meshes/finger_flex_collision.stl</uri>
          </mesh>
        </geometry>
        <surface>
          <contact>
            <ode/>
          </contact>
          <friction>
            <ode/>
          </friction>
        </surface>
      </collision>
      <visual name='hand_index_flex_1_link_visual'>
        <pose frame=''>0 0 0 0 -0 0</pose>
        <geometry>
          <mesh>
            <scale>1 1 1</scale>
            <uri>model://hey5_description/meshes/finger_flex_collision.stl</uri>
          </mesh>
        </geometry>
        <material>
          <script>
            <name>Gazebo/Black</name>
            <uri>file://media/materials/scripts/gazebo.material</uri>
          </script>
        </material>
      </visual>
      <gravity>1</gravity>
      <velocity_decay/>
    </link>
    <joint name='hand_index_flex_1_joint' type='revolute'>
      <child>hand_index_flex_1_link</child>
      <parent>hand_index_virtual_1_link</parent>
      <axis>
        <xyz>-0.5 0.866025 0.00069</xyz>
        <limit>
          <lower>0</lower>
          <upper>0.785398</upper>
          <effort>2</effort>
          <velocity>2</velocity>
        </limit>
        <dynamics>
          <damping>0.5</damping>
          <friction>0</friction>
          <spring_reference>0</spring_reference>
          <spring_stiffness>0</spring_stiffness>
        </dynamics>
        <use_parent_model_frame>1</use_parent_model_frame>
      </axis>
    </joint>
    <link name='hand_index_virtual_2_link'>
      <pose frame=''>1.10335 0.142003 1.44583 -1.57011 -0.000398 0.523599</pose>
      <inertial>
        <pose frame=''>0.0065 0 0 0 -0 0</pose>
        <mass>0.01</mass>
        <inertia>
          <ixx>0.001</ixx>
          <ixy>0</ixy>
          <ixz>0</ixz>
          <iyy>0.001</iyy>
          <iyz>0</iyz>
          <izz>0.001</izz>
        </inertia>
      </inertial>
      <collision name='hand_index_virtual_2_link_collision'>
        <pose frame=''>0 0 0 0 -0 0</pose>
        <geometry>
          <box>
            <size>0.013 0.002 0.012</size>
          </box>
        </geometry>
        <surface>
          <contact>
            <ode/>
          </contact>
          <friction>
            <ode/>
          </friction>
        </surface>
      </collision>
      <visual name='hand_index_virtual_2_link_visual'>
        <pose frame=''>0.0065 0 0 0 -0 0</pose>
        <geometry>
          <box>
            <size>0.013 0.002 0.012</size>
          </box>
        </geometry>
        <material>
          <script>
            <name>Gazebo/Black</name>
            <uri>file://media/materials/scripts/gazebo.material</uri>
          </script>
        </material>
      </visual>
      <gravity>1</gravity>
      <velocity_decay/>
    </link>
    <joint name='hand_index_virtual_2_joint' type='revolute'>
      <child>hand_index_virtual_2_link</child>
      <parent>hand_index_flex_1_link</parent>
      <axis>
        <xyz>-0.5 0.866025 0.00069</xyz>
        <limit>
          <lower>0</lower>
          <upper>0.785398</upper>
          <effort>2</effort>
          <velocity>2</velocity>
        </limit>
        <dynamics>
          <damping>0.5</damping>
          <friction>0</friction>
          <spring_reference>0</spring_reference>
          <spring_stiffness>0</spring_stiffness>
        </dynamics>
        <use_parent_model_frame>1</use_parent_model_frame>
      </axis>
    </joint>
    <link name='hand_index_flex_2_link'>
      <pose frame=''>1.11461 0.148503 1.44584 -1.57011 -0.000398 0.523599</pose>
      <inertial>
        <pose frame=''>0.0047 0.0031 0 0 -0 0</pose>
        <mass>0.009</mass>
        <inertia>
          <ixx>0.001</ixx>
          <ixy>0</ixy>
          <ixz>0</ixz>
          <iyy>0.001</iyy>
          <iyz>0</iyz>
          <izz>0.001</izz>
        </inertia>
      </inertial>
      <collision name='hand_index_flex_2_link_collision'>
        <pose frame=''>0 0 0 0 -0 0</pose>
        <geometry>
          <mesh>
            <scale>1 1 1</scale>
            <uri>model://hey5_description/meshes/finger_flex_collision.stl</uri>
          </mesh>
        </geometry>
        <surface>
          <contact>
            <ode/>
          </contact>
          <friction>
            <ode/>
          </friction>
        </surface>
      </collision>
      <visual name='hand_index_flex_2_link_visual'>
        <pose frame=''>0 0 0 0 -0 0</pose>
        <geometry>
          <mesh>
            <scale>1 1 1</scale>
            <uri>model://hey5_description/meshes/finger_flex_collision.stl</uri>
          </mesh>
        </geometry>
        <material>
          <script>
            <name>Gazebo/Black</name>
            <uri>file://media/materials/scripts/gazebo.material</uri>
          </script>
        </material>
      </visual>
      <gravity>1</gravity>
      <velocity_decay/>
    </link>
    <joint name='hand_index_flex_2_joint' type='revolute'>
      <child>hand_index_flex_2_link</child>
      <parent>hand_index_virtual_2_link</parent>
      <axis>
        <xyz>-0.5 0.866025 0.00069</xyz>
        <limit>
          <lower>0</lower>
          <upper>0.785398</upper>
          <effort>2</effort>
          <velocity>2</velocity>
        </limit>
        <dynamics>
          <damping>0.5</damping>
          <friction>0</friction>
          <spring_reference>0</spring_reference>
          <spring_stiffness>0</spring_stiffness>
        </dynamics>
        <use_parent_model_frame>1</use_parent_model_frame>
      </axis>
    </joint>
    <link name='hand_index_virtual_3_link'>
      <pose frame=''>1.1224 0.153003 1.44584 -1.57011 -0.000398 0.523599</pose>
      <inertial>
        <pose frame=''>0.0065 0 0 0 -0 0</pose>
        <mass>0.01</mass>
        <inertia>
          <ixx>0.001</ixx>
          <ixy>0</ixy>
          <ixz>0</ixz>
          <iyy>0.001</iyy>
          <iyz>0</iyz>
          <izz>0.001</izz>
        </inertia>
      </inertial>
      <collision name='hand_index_virtual_3_link_collision'>
        <pose frame=''>0 0 0 0 -0 0</pose>
        <geometry>
          <box>
            <size>0.013 0.002 0.012</size>
          </box>
        </geometry>
        <surface>
          <contact>
            <ode/>
          </contact>
          <friction>
            <ode/>
          </friction>
        </surface>
      </collision>
      <visual name='hand_index_virtual_3_link_visual'>
        <pose frame=''>0.0065 0 0 0 -0 0</pose>
        <geometry>
          <box>
            <size>0.013 0.002 0.012</size>
          </box>
        </geometry>
        <material>
          <script>
            <name>Gazebo/Black</name>
            <uri>file://media/materials/scripts/gazebo.material</uri>
          </script>
        </material>
      </visual>
      <gravity>1</gravity>
      <velocity_decay/>
    </link>
    <joint name='hand_index_virtual_3_joint' type='revolute'>
      <child>hand_index_virtual_3_link</child>
      <parent>hand_index_flex_2_link</parent>
      <axis>
        <xyz>-0.5 0.866025 0.00069</xyz>
        <limit>
          <lower>0</lower>
          <upper>0.785398</upper>
          <effort>2</effort>
          <velocity>2</velocity>
        </limit>
        <dynamics>
          <damping>0.5</damping>
          <friction>0</friction>
          <spring_reference>0</spring_reference>
          <spring_stiffness>0</spring_stiffness>
        </dynamics>
        <use_parent_model_frame>1</use_parent_model_frame>
      </axis>
    </joint>
    <link name='hand_index_flex_3_link'>
      <pose frame=''>1.13366 0.159503 1.44585 -1.57011 -0.000398 0.523599</pose>
      <inertial>
        <pose frame=''>0.0096 0.003 0 0 -0 0</pose>
        <mass>0.015</mass>
        <inertia>
          <ixx>0.001</ixx>
          <ixy>0</ixy>
          <ixz>0</ixz>
          <iyy>0.001</iyy>
          <iyz>0</iyz>
          <izz>0.001</izz>
        </inertia>
      </inertial>
      <collision name='hand_index_flex_3_link_collision'>
        <pose frame=''>0 0 0 0 -0 0</pose>
        <geometry>
          <mesh>
            <scale>1 1 1</scale>
            <uri>model://hey5_description/meshes/finger_flex_tip_collision.stl</uri>
          </mesh>
        </geometry>
        <surface>
          <contact>
            <ode/>
          </contact>
          <friction>
            <ode/>
          </friction>
        </surface>
      </collision>
      <visual name='hand_index_flex_3_link_visual'>
        <pose frame=''>0 0 0 0 -0 0</pose>
        <geometry>
          <mesh>
            <scale>1 1 1</scale>
            <uri>model://hey5_description/meshes/finger_flex_tip_collision.stl</uri>
          </mesh>
        </geometry>
        <material>
          <script>
            <name>Gazebo/Black</name>
            <uri>file://media/materials/scripts/gazebo.material</uri>
          </script>
        </material>
      </visual>
      <gravity>1</gravity>
      <velocity_decay/>
    </link>
    <joint name='hand_index_flex_3_joint' type='revolute'>
      <child>hand_index_flex_3_link</child>
      <parent>hand_index_virtual_3_link</parent>
      <axis>
        <xyz>-0.5 0.866025 0.00069</xyz>
        <limit>
          <lower>0</lower>
          <upper>0.785398</upper>
          <effort>2</effort>
          <velocity>2</velocity>
        </limit>
        <dynamics>
          <damping>0.5</damping>
          <friction>0</friction>
          <spring_reference>0</spring_reference>
          <spring_stiffness>0</spring_stiffness>
        </dynamics>
        <use_parent_model_frame>1</use_parent_model_frame>
      </axis>
    </joint>
    <link name='hand_index_link'>
      <pose frame=''>0.95 0.1 1.45 -1.57 0 0</pose>
      <inertial>
        <pose frame=''>0 0 0 0 -0 0</pose>
        <mass>0.05</mass>
        <inertia>
          <ixx>0.001</ixx>
          <ixy>0</ixy>
          <ixz>0</ixz>
          <iyy>0.001</iyy>
          <iyz>0</iyz>
          <izz>0.001</izz>
        </inertia>
      </inertial>
      <collision name='hand_index_link_collision'>
        <pose frame=''>0 0 0 0 -0 0</pose>
        <geometry>
          <sphere>
            <radius>0.001</radius>
          </sphere>
        </geometry>
      </collision>
      <visual name='hand_index_link_visual'>
        <pose frame=''>0 0 0 0 -0 0</pose>
        <geometry>
          <sphere>
            <radius>0.001</radius>
          </sphere>
        </geometry>
      </visual>
    </link>
    <joint name='hand_index_joint' type='revolute'>
      <child>hand_index_link</child>
      <parent>fore_link</parent>
      <axis>
        <xyz>0 1 0.000796</xyz>
        <limit>
          <lower>-3.05433</lower>
          <upper>6.80678</upper>
          <effort>2</effort>
          <velocity>3.35</velocity>
        </limit>
        <dynamics>
          <damping>0.5</damping>
          <friction>0</friction>
          <spring_reference>0</spring_reference>
          <spring_stiffness>0</spring_stiffness>
        </dynamics>
        <use_parent_model_frame>1</use_parent_model_frame>
      </axis>
    </joint>
    <link name='hand_little_abd_link'>
      <pose frame=''>1.0665 0.068003 1.44577 -3.1409 0.000398 -0.523599</pose>
      <inertial>
        <pose frame=''>-0.0018 0 0.0028 0 -0 0</pose>
        <mass>0.018</mass>
        <inertia>
          <ixx>0.001</ixx>
          <ixy>0</ixy>
          <ixz>0</ixz>
          <iyy>0.001</iyy>
          <iyz>0</iyz>
          <izz>0.001</izz>
        </inertia>
      </inertial>
      <collision name='hand_little_abd_link_collision'>
        <pose frame=''>0 0 0 0 -0 0</pose>
        <geometry>
          <mesh>
            <scale>1 1 1</scale>
            <uri>model://hey5_description/meshes/finger_abd_collision.stl</uri>
          </mesh>
        </geometry>
        <surface>
          <contact>
            <ode/>
          </contact>
          <friction>
            <ode/>
          </friction>
        </surface>
      </collision>
      <visual name='hand_little_abd_link_visual'>
        <pose frame=''>0 0 0 0 -0 0</pose>
        <geometry>
          <mesh>
            <scale>1 1 1</scale>
            <uri>model://hey5_description/meshes/finger_abd_collision.stl</uri>
          </mesh>
        </geometry>
        <material>
          <script>
            <name>Gazebo/Black</name>
            <uri>file://media/materials/scripts/gazebo.material</uri>
          </script>
        </material>
      </visual>
      <gravity>1</gravity>
      <velocity_decay/>
    </link>
    <joint name='hand_little_abd_joint' type='revolute'>
      <child>hand_little_abd_link</child>
      <parent>fore_link</parent>
      <axis>
        <xyz>0 0.000796 -1</xyz>
        <limit>
          <lower>-0.523599</lower>
          <upper>0.523599</upper>
          <effort>2</effort>
          <velocity>2</velocity>
        </limit>
        <dynamics>
          <damping>0.5</damping>
          <friction>0</friction>
          <spring_reference>0</spring_reference>
          <spring_stiffness>0</spring_stiffness>
        </dynamics>
        <use_parent_model_frame>1</use_parent_model_frame>
      </axis>
    </joint>
    <link name='hand_little_virtual_1_link'>
      <pose frame=''>1.07429 0.063503 1.44577 -1.57011 0.000398 -0.523599</pose>
      <inertial>
        <pose frame=''>0.0065 0 0 0 -0 0</pose>
        <mass>0.01</mass>
        <inertia>
          <ixx>0.001</ixx>
          <ixy>0</ixy>
          <ixz>0</ixz>
          <iyy>0.001</iyy>
          <iyz>0</iyz>
          <izz>0.001</izz>
        </inertia>
      </inertial>
      <collision name='hand_little_virtual_1_link_collision'>
        <pose frame=''>0 0 0 0 -0 0</pose>
        <geometry>
          <box>
            <size>0.013 0.002 0.012</size>
          </box>
        </geometry>
        <surface>
          <contact>
            <ode/>
          </contact>
          <friction>
            <ode/>
          </friction>
        </surface>
      </collision>
      <visual name='hand_little_virtual_1_link_visual'>
        <pose frame=''>0.0065 0 0 0 -0 0</pose>
        <geometry>
          <box>
            <size>0.013 0.002 0.012</size>
          </box>
        </geometry>
        <material>
          <script>
            <name>Gazebo/Black</name>
            <uri>file://media/materials/scripts/gazebo.material</uri>
          </script>
        </material>
      </visual>
      <gravity>1</gravity>
      <velocity_decay/>
    </link>
    <joint name='hand_little_virtual_1_joint' type='revolute'>
      <child>hand_little_virtual_1_link</child>
      <parent>hand_little_abd_link</parent>
      <axis>
        <xyz>0.5 0.866025 0.00069</xyz>
        <limit>
          <lower>0</lower>
          <upper>0.785398</upper>
          <effort>2</effort>
          <velocity>2</velocity>
        </limit>
        <dynamics>
          <damping>0.5</damping>
          <friction>0</friction>
          <spring_reference>0</spring_reference>
          <spring_stiffness>0</spring_stiffness>
        </dynamics>
        <use_parent_model_frame>1</use_parent_model_frame>
      </axis>
    </joint>
    <link name='hand_little_flex_1_link'>
      <pose frame=''>1.08555 0.057003 1.44577 -1.57011 0.000398 -0.523599</pose>
      <inertial>
        <pose frame=''>0.0047 0.0031 0 0 -0 0</pose>
        <mass>0.009</mass>
        <inertia>
          <ixx>0.001</ixx>
          <ixy>0</ixy>
          <ixz>0</ixz>
          <iyy>0.001</iyy>
          <iyz>0</iyz>
          <izz>0.001</izz>
        </inertia>
      </inertial>
      <collision name='hand_little_flex_1_link_collision'>
        <pose frame=''>0 0 0 0 -0 0</pose>
        <geometry>
          <mesh>
            <scale>1 1 1</scale>
            <uri>model://hey5_description/meshes/finger_flex_collision.stl</uri>
          </mesh>
        </geometry>
        <surface>
          <contact>
            <ode/>
          </contact>
          <friction>
            <ode/>
          </friction>
        </surface>
      </collision>
      <visual name='hand_little_flex_1_link_visual'>
        <pose frame=''>0 0 0 0 -0 0</pose>
        <geometry>
          <mesh>
            <scale>1 1 1</scale>
            <uri>model://hey5_description/meshes/finger_flex_collision.stl</uri>
          </mesh>
        </geometry>
        <material>
          <script>
            <name>Gazebo/Black</name>
            <uri>file://media/materials/scripts/gazebo.material</uri>
          </script>
        </material>
      </visual>
      <gravity>1</gravity>
      <velocity_decay/>
    </link>
    <joint name='hand_little_flex_1_joint' type='revolute'>
      <child>hand_little_flex_1_link</child>
      <parent>hand_little_virtual_1_link</parent>
      <axis>
        <xyz>0.5 0.866025 0.00069</xyz>
        <limit>
          <lower>0</lower>
          <upper>0.785398</upper>
          <effort>2</effort>
          <velocity>2</velocity>
        </limit>
        <dynamics>
          <damping>0.5</damping>
          <friction>0</friction>
          <spring_reference>0</spring_reference>
          <spring_stiffness>0</spring_stiffness>
        </dynamics>
        <use_parent_model_frame>1</use_parent_model_frame>
      </axis>
    </joint>
    <link name='hand_little_virtual_2_link'>
      <pose frame=''>1.09335 0.052503 1.44576 -1.57011 0.000398 -0.523599</pose>
      <inertial>
        <pose frame=''>0.0065 0 0 0 -0 0</pose>
        <mass>0.01</mass>
        <inertia>
          <ixx>0.001</ixx>
          <ixy>0</ixy>
          <ixz>0</ixz>
          <iyy>0.001</iyy>
          <iyz>0</iyz>
          <izz>0.001</izz>
        </inertia>
      </inertial>
      <collision name='hand_little_virtual_2_link_collision'>
        <pose frame=''>0 0 0 0 -0 0</pose>
        <geometry>
          <box>
            <size>0.013 0.002 0.012</size>
          </box>
        </geometry>
        <surface>
          <contact>
            <ode/>
          </contact>
          <friction>
            <ode/>
          </friction>
        </surface>
      </collision>
      <visual name='hand_little_virtual_2_link_visual'>
        <pose frame=''>0.0065 0 0 0 -0 0</pose>
        <geometry>
          <box>
            <size>0.013 0.002 0.012</size>
          </box>
        </geometry>
        <material>
          <script>
            <name>Gazebo/Black</name>
            <uri>file://media/materials/scripts/gazebo.material</uri>
          </script>
        </material>
      </visual>
      <gravity>1</gravity>
      <velocity_decay/>
    </link>
    <joint name='hand_little_virtual_2_joint' type='revolute'>
      <child>hand_little_virtual_2_link</child>
      <parent>hand_little_flex_1_link</parent>
      <axis>
        <xyz>0.5 0.866025 0.00069</xyz>
        <limit>
          <lower>0</lower>
          <upper>0.785398</upper>
          <effort>2</effort>
          <velocity>2</velocity>
        </limit>
        <dynamics>
          <damping>0.5</damping>
          <friction>0</friction>
          <spring_reference>0</spring_reference>
          <spring_stiffness>0</spring_stiffness>
        </dynamics>
        <use_parent_model_frame>1</use_parent_model_frame>
      </axis>
    </joint>
    <link name='hand_little_flex_2_link'>
      <pose frame=''>1.10461 0.046003 1.44576 -1.57011 0.000398 -0.523599</pose>
      <inertial>
        <pose frame=''>0.0047 0.0031 0 0 -0 0</pose>
        <mass>0.009</mass>
        <inertia>
          <ixx>0.001</ixx>
          <ixy>0</ixy>
          <ixz>0</ixz>
          <iyy>0.001</iyy>
          <iyz>0</iyz>
          <izz>0.001</izz>
        </inertia>
      </inertial>
      <collision name='hand_little_flex_2_link_collision'>
        <pose frame=''>0 0 0 0 -0 0</pose>
        <geometry>
          <mesh>
            <scale>1 1 1</scale>
            <uri>model://hey5_description/meshes/finger_flex_collision.stl</uri>
          </mesh>
        </geometry>
        <surface>
          <contact>
            <ode/>
          </contact>
          <friction>
            <ode/>
          </friction>
        </surface>
      </collision>
      <visual name='hand_little_flex_2_link_visual'>
        <pose frame=''>0 0 0 0 -0 0</pose>
        <geometry>
          <mesh>
            <scale>1 1 1</scale>
            <uri>model://hey5_description/meshes/finger_flex_collision.stl</uri>
          </mesh>
        </geometry>
        <material>
          <script>
            <name>Gazebo/Black</name>
            <uri>file://media/materials/scripts/gazebo.material</uri>
          </script>
        </material>
      </visual>
      <gravity>1</gravity>
      <velocity_decay/>
    </link>
    <joint name='hand_little_flex_2_joint' type='revolute'>
      <child>hand_little_flex_2_link</child>
      <parent>hand_little_virtual_2_link</parent>
      <axis>
        <xyz>0.5 0.866025 0.00069</xyz>
        <limit>
          <lower>0</lower>
          <upper>0.785398</upper>
          <effort>2</effort>
          <velocity>2</velocity>
        </limit>
        <dynamics>
          <damping>0.5</damping>
          <friction>0</friction>
          <spring_reference>0</spring_reference>
          <spring_stiffness>0</spring_stiffness>
        </dynamics>
        <use_parent_model_frame>1</use_parent_model_frame>
      </axis>
    </joint>
    <link name='hand_little_virtual_3_link'>
      <pose frame=''>1.1124 0.041503 1.44575 -1.57011 0.000398 -0.523599</pose>
      <inertial>
        <pose frame=''>0.0065 0 0 0 -0 0</pose>
        <mass>0.01</mass>
        <inertia>
          <ixx>0.001</ixx>
          <ixy>0</ixy>
          <ixz>0</ixz>
          <iyy>0.001</iyy>
          <iyz>0</iyz>
          <izz>0.001</izz>
        </inertia>
      </inertial>
      <collision name='hand_little_virtual_3_link_collision'>
        <pose frame=''>0 0 0 0 -0 0</pose>
        <geometry>
          <box>
            <size>0.013 0.002 0.012</size>
          </box>
        </geometry>
        <surface>
          <contact>
            <ode/>
          </contact>
          <friction>
            <ode/>
          </friction>
        </surface>
      </collision>
      <visual name='hand_little_virtual_3_link_visual'>
        <pose frame=''>0.0065 0 0 0 -0 0</pose>
        <geometry>
          <box>
            <size>0.013 0.002 0.012</size>
          </box>
        </geometry>
        <material>
          <script>
            <name>Gazebo/Black</name>
            <uri>file://media/materials/scripts/gazebo.material</uri>
          </script>
        </material>
      </visual>
      <gravity>1</gravity>
      <velocity_decay/>
    </link>
    <joint name='hand_little_virtual_3_joint' type='revolute'>
      <child>hand_little_virtual_3_link</child>
      <parent>hand_little_flex_2_link</parent>
      <axis>
        <xyz>0.5 0.866025 0.00069</xyz>
        <limit>
          <lower>0</lower>
          <upper>0.785398</upper>
          <effort>2</effort>
          <velocity>2</velocity>
        </limit>
        <dynamics>
          <damping>0.5</damping>
          <friction>0</friction>
          <spring_reference>0</spring_reference>
          <spring_stiffness>0</spring_stiffness>
        </dynamics>
        <use_parent_model_frame>1</use_parent_model_frame>
      </axis>
    </joint>
    <link name='hand_little_flex_3_link'>
      <pose frame=''>1.12366 0.035003 1.44575 -1.57011 0.000398 -0.523599</pose>
      <inertial>
        <pose frame=''>0.0096 0.003 0 0 -0 0</pose>
        <mass>0.015</mass>
        <inertia>
          <ixx>0.001</ixx>
          <ixy>0</ixy>
          <ixz>0</ixz>
          <iyy>0.001</iyy>
          <iyz>0</iyz>
          <izz>0.001</izz>
        </inertia>
      </inertial>
      <collision name='hand_little_flex_3_link_collision'>
        <pose frame=''>0 0 0 0 -0 0</pose>
        <geometry>
          <mesh>
            <scale>1 1 1</scale>
            <uri>model://hey5_description/meshes/finger_flex_tip_collision.stl</uri>
          </mesh>
        </geometry>
        <surface>
          <contact>
            <ode/>
          </contact>
          <friction>
            <ode/>
          </friction>
        </surface>
      </collision>
      <visual name='hand_little_flex_3_link_visual'>
        <pose frame=''>0 0 0 0 -0 0</pose>
        <geometry>
          <mesh>
            <scale>1 1 1</scale>
            <uri>model://hey5_description/meshes/finger_flex_tip_collision.stl</uri>
          </mesh>
        </geometry>
        <material>
          <script>
            <name>Gazebo/Black</name>
            <uri>file://media/materials/scripts/gazebo.material</uri>
          </script>
        </material>
      </visual>
      <gravity>1</gravity>
      <velocity_decay/>
    </link>
    <joint name='hand_little_flex_3_joint' type='revolute'>
      <child>hand_little_flex_3_link</child>
      <parent>hand_little_virtual_3_link</parent>
      <axis>
        <xyz>0.5 0.866025 0.00069</xyz>
        <limit>
          <lower>0</lower>
          <upper>0.785398</upper>
          <effort>2</effort>
          <velocity>2</velocity>
        </limit>
        <dynamics>
          <damping>0.5</damping>
          <friction>0</friction>
          <spring_reference>0</spring_reference>
          <spring_stiffness>0</spring_stiffness>
        </dynamics>
        <use_parent_model_frame>1</use_parent_model_frame>
      </axis>
    </joint>
    <link name='hand_middle_abd_link'>
      <pose frame=''>1.0835 0.107003 1.44581 -3.1408 0 0</pose>
      <inertial>
        <pose frame=''>-0.0018 0 0.0028 0 -0 0</pose>
        <mass>0.018</mass>
        <inertia>
          <ixx>0.001</ixx>
          <ixy>0</ixy>
          <ixz>0</ixz>
          <iyy>0.001</iyy>
          <iyz>0</iyz>
          <izz>0.001</izz>
        </inertia>
      </inertial>
      <collision name='hand_middle_abd_link_collision'>
        <pose frame=''>0 0 0 0 -0 0</pose>
        <geometry>
          <mesh>
            <scale>1 1 1</scale>
            <uri>model://hey5_description/meshes/finger_abd_collision.stl</uri>
          </mesh>
        </geometry>
        <surface>
          <contact>
            <ode/>
          </contact>
          <friction>
            <ode/>
          </friction>
        </surface>
      </collision>
      <visual name='hand_middle_abd_link_visual'>
        <pose frame=''>0 0 0 0 -0 0</pose>
        <geometry>
          <mesh>
            <scale>1 1 1</scale>
            <uri>model://hey5_description/meshes/finger_abd_collision.stl</uri>
          </mesh>
        </geometry>
        <material>
          <script>
            <name>Gazebo/Black</name>
            <uri>file://media/materials/scripts/gazebo.material</uri>
          </script>
        </material>
      </visual>
      <gravity>1</gravity>
      <velocity_decay/>
    </link>
    <joint name='hand_middle_abd_joint' type='revolute'>
      <child>hand_middle_abd_link</child>
      <parent>fore_link</parent>
      <axis>
        <xyz>0 0.000796 -1</xyz>
        <limit>
          <lower>-0.523599</lower>
          <upper>0.523599</upper>
          <effort>2</effort>
          <velocity>2</velocity>
        </limit>
        <dynamics>
          <damping>0.5</damping>
          <friction>0</friction>
          <spring_reference>0</spring_reference>
          <spring_stiffness>0</spring_stiffness>
        </dynamics>
        <use_parent_model_frame>1</use_parent_model_frame>
      </axis>
    </joint>
    <link name='hand_middle_virtual_1_link'>
      <pose frame=''>1.0925 0.107003 1.44581 -1.57 0 0</pose>
      <inertial>
        <pose frame=''>0.0065 0 0 0 -0 0</pose>
        <mass>0.01</mass>
        <inertia>
          <ixx>0.001</ixx>
          <ixy>0</ixy>
          <ixz>0</ixz>
          <iyy>0.001</iyy>
          <iyz>0</iyz>
          <izz>0.001</izz>
        </inertia>
      </inertial>
      <collision name='hand_middle_virtual_1_link_collision'>
        <pose frame=''>0 0 0 0 -0 0</pose>
        <geometry>
          <box>
            <size>0.013 0.002 0.012</size>
          </box>
        </geometry>
        <surface>
          <contact>
            <ode/>
          </contact>
          <friction>
            <ode/>
          </friction>
        </surface>
      </collision>
      <visual name='hand_middle_virtual_1_link_visual'>
        <pose frame=''>0.0065 0 0 0 -0 0</pose>
        <geometry>
          <box>
            <size>0.013 0.002 0.012</size>
          </box>
        </geometry>
        <material>
          <script>
            <name>Gazebo/Black</name>
            <uri>file://media/materials/scripts/gazebo.material</uri>
          </script>
        </material>
      </visual>
      <gravity>1</gravity>
      <velocity_decay/>
    </link>
    <joint name='hand_middle_virtual_1_joint' type='revolute'>
      <child>hand_middle_virtual_1_link</child>
      <parent>hand_middle_abd_link</parent>
      <axis>
        <xyz>0 1 0.000796</xyz>
        <limit>
          <lower>0</lower>
          <upper>0.785398</upper>
          <effort>2</effort>
          <velocity>2</velocity>
        </limit>
        <dynamics>
          <damping>0.5</damping>
          <friction>0</friction>
          <spring_reference>0</spring_reference>
          <spring_stiffness>0</spring_stiffness>
        </dynamics>
        <use_parent_model_frame>1</use_parent_model_frame>
      </axis>
    </joint>
    <link name='hand_middle_flex_1_link'>
      <pose frame=''>1.1055 0.107003 1.44581 -1.57 0 0</pose>
      <inertial>
        <pose frame=''>0.0047 0.0031 0 0 -0 0</pose>
        <mass>0.009</mass>
        <inertia>
          <ixx>0.001</ixx>
          <ixy>0</ixy>
          <ixz>0</ixz>
          <iyy>0.001</iyy>
          <iyz>0</iyz>
          <izz>0.001</izz>
        </inertia>
      </inertial>
      <collision name='hand_middle_flex_1_link_collision'>
        <pose frame=''>0 0 0 0 -0 0</pose>
        <geometry>
          <mesh>
            <scale>1 1 1</scale>
            <uri>model://hey5_description/meshes/finger_flex_collision.stl</uri>
          </mesh>
        </geometry>
        <surface>
          <contact>
            <ode/>
          </contact>
          <friction>
            <ode/>
          </friction>
        </surface>
      </collision>
      <visual name='hand_middle_flex_1_link_visual'>
        <pose frame=''>0 0 0 0 -0 0</pose>
        <geometry>
          <mesh>
            <scale>1 1 1</scale>
            <uri>model://hey5_description/meshes/finger_flex_collision.stl</uri>
          </mesh>
        </geometry>
        <material>
          <script>
            <name>Gazebo/Black</name>
            <uri>file://media/materials/scripts/gazebo.material</uri>
          </script>
        </material>
      </visual>
      <gravity>1</gravity>
      <velocity_decay/>
    </link>
    <joint name='hand_middle_flex_1_joint' type='revolute'>
      <child>hand_middle_flex_1_link</child>
      <parent>hand_middle_virtual_1_link</parent>
      <axis>
        <xyz>0 1 0.000796</xyz>
        <limit>
          <lower>0</lower>
          <upper>0.785398</upper>
          <effort>2</effort>
          <velocity>2</velocity>
        </limit>
        <dynamics>
          <damping>0.5</damping>
          <friction>0</friction>
          <spring_reference>0</spring_reference>
          <spring_stiffness>0</spring_stiffness>
        </dynamics>
        <use_parent_model_frame>1</use_parent_model_frame>
      </axis>
    </joint>
    <link name='hand_middle_virtual_2_link'>
      <pose frame=''>1.1145 0.107003 1.44581 -1.57 0 0</pose>
      <inertial>
        <pose frame=''>0.0065 0 0 0 -0 0</pose>
        <mass>0.01</mass>
        <inertia>
          <ixx>0.001</ixx>
          <ixy>0</ixy>
          <ixz>0</ixz>
          <iyy>0.001</iyy>
          <iyz>0</iyz>
          <izz>0.001</izz>
        </inertia>
      </inertial>
      <collision name='hand_middle_virtual_2_link_collision'>
        <pose frame=''>0 0 0 0 -0 0</pose>
        <geometry>
          <box>
            <size>0.013 0.002 0.012</size>
          </box>
        </geometry>
        <surface>
          <contact>
            <ode/>
          </contact>
          <friction>
            <ode/>
          </friction>
        </surface>
      </collision>
      <visual name='hand_middle_virtual_2_link_visual'>
        <pose frame=''>0.0065 0 0 0 -0 0</pose>
        <geometry>
          <box>
            <size>0.013 0.002 0.012</size>
          </box>
        </geometry>
        <material>
          <script>
            <name>Gazebo/Black</name>
            <uri>file://media/materials/scripts/gazebo.material</uri>
          </script>
        </material>
      </visual>
      <gravity>1</gravity>
      <velocity_decay/>
    </link>
    <joint name='hand_middle_virtual_2_joint' type='revolute'>
      <child>hand_middle_virtual_2_link</child>
      <parent>hand_middle_flex_1_link</parent>
      <axis>
        <xyz>0 1 0.000796</xyz>
        <limit>
          <lower>0</lower>
          <upper>0.785398</upper>
          <effort>2</effort>
          <velocity>2</velocity>
        </limit>
        <dynamics>
          <damping>0.5</damping>
          <friction>0</friction>
          <spring_reference>0</spring_reference>
          <spring_stiffness>0</spring_stiffness>
        </dynamics>
        <use_parent_model_frame>1</use_parent_model_frame>
      </axis>
    </joint>
    <link name='hand_middle_flex_2_link'>
      <pose frame=''>1.1275 0.107003 1.44581 -1.57 0 0</pose>
      <inertial>
        <pose frame=''>0.0047 0.0031 0 0 -0 0</pose>
        <mass>0.009</mass>
        <inertia>
          <ixx>0.001</ixx>
          <ixy>0</ixy>
          <ixz>0</ixz>
          <iyy>0.001</iyy>
          <iyz>0</iyz>
          <izz>0.001</izz>
        </inertia>
      </inertial>
      <collision name='hand_middle_flex_2_link_collision'>
        <pose frame=''>0 0 0 0 -0 0</pose>
        <geometry>
          <mesh>
            <scale>1 1 1</scale>
            <uri>model://hey5_description/meshes/finger_flex_collision.stl</uri>
          </mesh>
        </geometry>
        <surface>
          <contact>
            <ode/>
          </contact>
          <friction>
            <ode/>
          </friction>
        </surface>
      </collision>
      <visual name='hand_middle_flex_2_link_visual'>
        <pose frame=''>0 0 0 0 -0 0</pose>
        <geometry>
          <mesh>
            <scale>1 1 1</scale>
            <uri>model://hey5_description/meshes/finger_flex_collision.stl</uri>
          </mesh>
        </geometry>
        <material>
          <script>
            <name>Gazebo/Black</name>
            <uri>file://media/materials/scripts/gazebo.material</uri>
          </script>
        </material>
      </visual>
      <gravity>1</gravity>
      <velocity_decay/>
    </link>
    <joint name='hand_middle_flex_2_joint' type='revolute'>
      <child>hand_middle_flex_2_link</child>
      <parent>hand_middle_virtual_2_link</parent>
      <axis>
        <xyz>0 1 0.000796</xyz>
        <limit>
          <lower>0</lower>
          <upper>0.785398</upper>
          <effort>2</effort>
          <velocity>2</velocity>
        </limit>
        <dynamics>
          <damping>0.5</damping>
          <friction>0</friction>
          <spring_reference>0</spring_reference>
          <spring_stiffness>0</spring_stiffness>
        </dynamics>
        <use_parent_model_frame>1</use_parent_model_frame>
      </axis>
    </joint>
    <link name='hand_middle_virtual_3_link'>
      <pose frame=''>1.1365 0.107003 1.44581 -1.57 0 0</pose>
      <inertial>
        <pose frame=''>0.0065 0 0 0 -0 0</pose>
        <mass>0.01</mass>
        <inertia>
          <ixx>0.001</ixx>
          <ixy>0</ixy>
          <ixz>0</ixz>
          <iyy>0.001</iyy>
          <iyz>0</iyz>
          <izz>0.001</izz>
        </inertia>
      </inertial>
      <collision name='hand_middle_virtual_3_link_collision'>
        <pose frame=''>0 0 0 0 -0 0</pose>
        <geometry>
          <box>
            <size>0.013 0.002 0.012</size>
          </box>
        </geometry>
        <surface>
          <contact>
            <ode/>
          </contact>
          <friction>
            <ode/>
          </friction>
        </surface>
      </collision>
      <visual name='hand_middle_virtual_3_link_visual'>
        <pose frame=''>0.0065 0 0 0 -0 0</pose>
        <geometry>
          <box>
            <size>0.013 0.002 0.012</size>
          </box>
        </geometry>
        <material>
          <script>
            <name>Gazebo/Black</name>
            <uri>file://media/materials/scripts/gazebo.material</uri>
          </script>
        </material>
      </visual>
      <gravity>1</gravity>
      <velocity_decay/>
    </link>
    <joint name='hand_middle_virtual_3_joint' type='revolute'>
      <child>hand_middle_virtual_3_link</child>
      <parent>hand_middle_flex_2_link</parent>
      <axis>
        <xyz>0 1 0.000796</xyz>
        <limit>
          <lower>0</lower>
          <upper>0.785398</upper>
          <effort>2</effort>
          <velocity>2</velocity>
        </limit>
        <dynamics>
          <damping>0.5</damping>
          <friction>0</friction>
          <spring_reference>0</spring_reference>
          <spring_stiffness>0</spring_stiffness>
        </dynamics>
        <use_parent_model_frame>1</use_parent_model_frame>
      </axis>
    </joint>
    <link name='hand_middle_flex_3_link'>
      <pose frame=''>1.1495 0.107003 1.44581 -1.57 0 0</pose>
      <inertial>
        <pose frame=''>0.0096 0.003 0 0 -0 0</pose>
        <mass>0.015</mass>
        <inertia>
          <ixx>0.001</ixx>
          <ixy>0</ixy>
          <ixz>0</ixz>
          <iyy>0.001</iyy>
          <iyz>0</iyz>
          <izz>0.001</izz>
        </inertia>
      </inertial>
      <collision name='hand_middle_flex_3_link_collision'>
        <pose frame=''>0 0 0 0 -0 0</pose>
        <geometry>
          <mesh>
            <scale>1 1 1</scale>
            <uri>model://hey5_description/meshes/finger_flex_tip_collision.stl</uri>
          </mesh>
        </geometry>
        <surface>
          <contact>
            <ode/>
          </contact>
          <friction>
            <ode/>
          </friction>
        </surface>
      </collision>
      <visual name='hand_middle_flex_3_link_visual'>
        <pose frame=''>0 0 0 0 -0 0</pose>
        <geometry>
          <mesh>
            <scale>1 1 1</scale>
            <uri>model://hey5_description/meshes/finger_flex_tip_collision.stl</uri>
          </mesh>
        </geometry>
        <material>
          <script>
            <name>Gazebo/Black</name>
            <uri>file://media/materials/scripts/gazebo.material</uri>
          </script>
        </material>
      </visual>
      <gravity>1</gravity>
      <velocity_decay/>
    </link>
    <joint name='hand_middle_flex_3_joint' type='revolute'>
      <child>hand_middle_flex_3_link</child>
      <parent>hand_middle_virtual_3_link</parent>
      <axis>
        <xyz>0 1 0.000796</xyz>
        <limit>
          <lower>0</lower>
          <upper>0.785398</upper>
          <effort>2</effort>
          <velocity>2</velocity>
        </limit>
        <dynamics>
          <damping>0.5</damping>
          <friction>0</friction>
          <spring_reference>0</spring_reference>
          <spring_stiffness>0</spring_stiffness>
        </dynamics>
        <use_parent_model_frame>1</use_parent_model_frame>
      </axis>
    </joint>
    <link name='hand_mrl_link'>
      <pose frame=''>0.95 0.1 1.45 -1.57 0 0</pose>
      <inertial>
        <pose frame=''>0 0 0 0 -0 0</pose>
        <mass>0.05</mass>
        <inertia>
          <ixx>0.001</ixx>
          <ixy>0</ixy>
          <ixz>0</ixz>
          <iyy>0.001</iyy>
          <iyz>0</iyz>
          <izz>0.001</izz>
        </inertia>
      </inertial>
      <collision name='hand_mrl_link_collision'>
        <pose frame=''>0 0 0 0 -0 0</pose>
        <geometry>
          <sphere>
            <radius>0.001</radius>
          </sphere>
        </geometry>
      </collision>
      <visual name='hand_mrl_link_visual'>
        <pose frame=''>0 0 0 0 -0 0</pose>
        <geometry>
          <sphere>
            <radius>0.001</radius>
          </sphere>
        </geometry>
      </visual>
    </link>
    <joint name='hand_mrl_joint' type='revolute'>
      <child>hand_mrl_link</child>
      <parent>fore_link</parent>
      <axis>
        <xyz>0 1 0.000796</xyz>
        <limit>
          <lower>-2.53073</lower>
          <upper>9.25025</upper>
          <effort>2</effort>
          <velocity>3.56</velocity>
        </limit>
        <dynamics>
          <damping>0.5</damping>
          <friction>0</friction>
          <spring_reference>0</spring_reference>
          <spring_stiffness>0</spring_stiffness>
        </dynamics>
        <use_parent_model_frame>1</use_parent_model_frame>
      </axis>
    </joint>
    <link name='hand_ring_abd_link'>
      <pose frame=''>1.0765 0.087503 1.44579 -3.14082 0.000206 -0.261799</pose>
      <inertial>
        <pose frame=''>-0.0018 0 0.0028 0 -0 0</pose>
        <mass>0.018</mass>
        <inertia>
          <ixx>0.001</ixx>
          <ixy>0</ixy>
          <ixz>0</ixz>
          <iyy>0.001</iyy>
          <iyz>0</iyz>
          <izz>0.001</izz>
        </inertia>
      </inertial>
      <collision name='hand_ring_abd_link_collision'>
        <pose frame=''>0 0 0 0 -0 0</pose>
        <geometry>
          <mesh>
            <scale>1 1 1</scale>
            <uri>model://hey5_description/meshes/finger_abd_collision.stl</uri>
          </mesh>
        </geometry>
        <surface>
          <contact>
            <ode/>
          </contact>
          <friction>
            <ode/>
          </friction>
        </surface>
      </collision>
      <visual name='hand_ring_abd_link_visual'>
        <pose frame=''>0 0 0 0 -0 0</pose>
        <geometry>
          <mesh>
            <scale>1 1 1</scale>
            <uri>model://hey5_description/meshes/finger_abd_collision.stl</uri>
          </mesh>
        </geometry>
        <material>
          <script>
            <name>Gazebo/Black</name>
            <uri>file://media/materials/scripts/gazebo.material</uri>
          </script>
        </material>
      </visual>
      <gravity>1</gravity>
      <velocity_decay/>
    </link>
    <joint name='hand_ring_abd_joint' type='revolute'>
      <child>hand_ring_abd_link</child>
      <parent>fore_link</parent>
      <axis>
        <xyz>0 0.000796 -1</xyz>
        <limit>
          <lower>-0.523599</lower>
          <upper>0.523599</upper>
          <effort>2</effort>
          <velocity>2</velocity>
        </limit>
        <dynamics>
          <damping>0.5</damping>
          <friction>0</friction>
          <spring_reference>0</spring_reference>
          <spring_stiffness>0</spring_stiffness>
        </dynamics>
        <use_parent_model_frame>1</use_parent_model_frame>
      </axis>
    </joint>
    <link name='hand_ring_virtual_1_link'>
      <pose frame=''>1.08519 0.085174 1.44579 -1.57003 0.000206 -0.261799</pose>
      <inertial>
        <pose frame=''>0.0065 0 0 0 -0 0</pose>
        <mass>0.01</mass>
        <inertia>
          <ixx>0.001</ixx>
          <ixy>0</ixy>
          <ixz>0</ixz>
          <iyy>0.001</iyy>
          <iyz>0</iyz>
          <izz>0.001</izz>
        </inertia>
      </inertial>
      <collision name='hand_ring_virtual_1_link_collision'>
        <pose frame=''>0 0 0 0 -0 0</pose>
        <geometry>
          <box>
            <size>0.013 0.002 0.012</size>
          </box>
        </geometry>
        <surface>
          <contact>
            <ode/>
          </contact>
          <friction>
            <ode/>
          </friction>
        </surface>
      </collision>
      <visual name='hand_ring_virtual_1_link_visual'>
        <pose frame=''>0.0065 0 0 0 -0 0</pose>
        <geometry>
          <box>
            <size>0.013 0.002 0.012</size>
          </box>
        </geometry>
        <material>
          <script>
            <name>Gazebo/Black</name>
            <uri>file://media/materials/scripts/gazebo.material</uri>
          </script>
        </material>
      </visual>
      <gravity>1</gravity>
      <velocity_decay/>
    </link>
    <joint name='hand_ring_virtual_1_joint' type='revolute'>
      <child>hand_ring_virtual_1_link</child>
      <parent>hand_ring_abd_link</parent>
      <axis>
        <xyz>0.258819 0.965926 0.000769</xyz>
        <limit>
          <lower>0</lower>
          <upper>0.785398</upper>
          <effort>2</effort>
          <velocity>2</velocity>
        </limit>
        <dynamics>
          <damping>0.5</damping>
          <friction>0</friction>
          <spring_reference>0</spring_reference>
          <spring_stiffness>0</spring_stiffness>
        </dynamics>
        <use_parent_model_frame>1</use_parent_model_frame>
      </axis>
    </joint>
    <link name='hand_ring_flex_1_link'>
      <pose frame=''>1.09775 0.081809 1.44579 -1.57003 0.000206 -0.261799</pose>
      <inertial>
        <pose frame=''>0.0047 0.0031 0 0 -0 0</pose>
        <mass>0.009</mass>
        <inertia>
          <ixx>0.001</ixx>
          <ixy>0</ixy>
          <ixz>0</ixz>
          <iyy>0.001</iyy>
          <iyz>0</iyz>
          <izz>0.001</izz>
        </inertia>
      </inertial>
      <collision name='hand_ring_flex_1_link_collision'>
        <pose frame=''>0 0 0 0 -0 0</pose>
        <geometry>
          <mesh>
            <scale>1 1 1</scale>
            <uri>model://hey5_description/meshes/finger_flex_collision.stl</uri>
          </mesh>
        </geometry>
        <surface>
          <contact>
            <ode/>
          </contact>
          <friction>
            <ode/>
          </friction>
        </surface>
      </collision>
      <visual name='hand_ring_flex_1_link_visual'>
        <pose frame=''>0 0 0 0 -0 0</pose>
        <geometry>
          <mesh>
            <scale>1 1 1</scale>
            <uri>model://hey5_description/meshes/finger_flex_collision.stl</uri>
          </mesh>
        </geometry>
        <material>
          <script>
            <name>Gazebo/Black</name>
            <uri>file://media/materials/scripts/gazebo.material</uri>
          </script>
        </material>
      </visual>
      <gravity>1</gravity>
      <velocity_decay/>
    </link>
    <joint name='hand_ring_flex_1_joint' type='revolute'>
      <child>hand_ring_flex_1_link</child>
      <parent>hand_ring_virtual_1_link</parent>
      <axis>
        <xyz>0.258819 0.965926 0.000769</xyz>
        <limit>
          <lower>0</lower>
          <upper>0.785398</upper>
          <effort>2</effort>
          <velocity>2</velocity>
        </limit>
        <dynamics>
          <damping>0.5</damping>
          <friction>0</friction>
          <spring_reference>0</spring_reference>
          <spring_stiffness>0</spring_stiffness>
        </dynamics>
        <use_parent_model_frame>1</use_parent_model_frame>
      </axis>
    </joint>
    <link name='hand_ring_virtual_2_link'>
      <pose frame=''>1.10644 0.07948 1.44578 -1.57003 0.000206 -0.261799</pose>
      <inertial>
        <pose frame=''>0.0065 0 0 0 -0 0</pose>
        <mass>0.01</mass>
        <inertia>
          <ixx>0.001</ixx>
          <ixy>0</ixy>
          <ixz>0</ixz>
          <iyy>0.001</iyy>
          <iyz>0</iyz>
          <izz>0.001</izz>
        </inertia>
      </inertial>
      <collision name='hand_ring_virtual_2_link_collision'>
        <pose frame=''>0 0 0 0 -0 0</pose>
        <geometry>
          <box>
            <size>0.013 0.002 0.012</size>
          </box>
        </geometry>
        <surface>
          <contact>
            <ode/>
          </contact>
          <friction>
            <ode/>
          </friction>
        </surface>
      </collision>
      <visual name='hand_ring_virtual_2_link_visual'>
        <pose frame=''>0.0065 0 0 0 -0 0</pose>
        <geometry>
          <box>
            <size>0.013 0.002 0.012</size>
          </box>
        </geometry>
        <material>
          <script>
            <name>Gazebo/Black</name>
            <uri>file://media/materials/scripts/gazebo.material</uri>
          </script>
        </material>
      </visual>
      <gravity>1</gravity>
      <velocity_decay/>
    </link>
    <joint name='hand_ring_virtual_2_joint' type='revolute'>
      <child>hand_ring_virtual_2_link</child>
      <parent>hand_ring_flex_1_link</parent>
      <axis>
        <xyz>0.258819 0.965926 0.000769</xyz>
        <limit>
          <lower>0</lower>
          <upper>0.785398</upper>
          <effort>2</effort>
          <velocity>2</velocity>
        </limit>
        <dynamics>
          <damping>0.5</damping>
          <friction>0</friction>
          <spring_reference>0</spring_reference>
          <spring_stiffness>0</spring_stiffness>
        </dynamics>
        <use_parent_model_frame>1</use_parent_model_frame>
      </axis>
    </joint>
    <link name='hand_ring_flex_2_link'>
      <pose frame=''>1.119 0.076115 1.44578 -1.57003 0.000206 -0.261799</pose>
      <inertial>
        <pose frame=''>0.0047 0.0031 0 0 -0 0</pose>
        <mass>0.009</mass>
        <inertia>
          <ixx>0.001</ixx>
          <ixy>0</ixy>
          <ixz>0</ixz>
          <iyy>0.001</iyy>
          <iyz>0</iyz>
          <izz>0.001</izz>
        </inertia>
      </inertial>
      <collision name='hand_ring_flex_2_link_collision'>
        <pose frame=''>0 0 0 0 -0 0</pose>
        <geometry>
          <mesh>
            <scale>1 1 1</scale>
            <uri>model://hey5_description/meshes/finger_flex_collision.stl</uri>
          </mesh>
        </geometry>
        <surface>
          <contact>
            <ode/>
          </contact>
          <friction>
            <ode/>
          </friction>
        </surface>
      </collision>
      <visual name='hand_ring_flex_2_link_visual'>
        <pose frame=''>0 0 0 0 -0 0</pose>
        <geometry>
          <mesh>
            <scale>1 1 1</scale>
            <uri>model://hey5_description/meshes/finger_flex_collision.stl</uri>
          </mesh>
        </geometry>
        <material>
          <script>
            <name>Gazebo/Black</name>
            <uri>file://media/materials/scripts/gazebo.material</uri>
          </script>
        </material>
      </visual>
      <gravity>1</gravity>
      <velocity_decay/>
    </link>
    <joint name='hand_ring_flex_2_joint' type='revolute'>
      <child>hand_ring_flex_2_link</child>
      <parent>hand_ring_virtual_2_link</parent>
      <axis>
        <xyz>0.258819 0.965926 0.000769</xyz>
        <limit>
          <lower>0</lower>
          <upper>0.785398</upper>
          <effort>2</effort>
          <velocity>2</velocity>
        </limit>
        <dynamics>
          <damping>0.5</damping>
          <friction>0</friction>
          <spring_reference>0</spring_reference>
          <spring_stiffness>0</spring_stiffness>
        </dynamics>
        <use_parent_model_frame>1</use_parent_model_frame>
      </axis>
    </joint>
    <link name='hand_ring_virtual_3_link'>
      <pose frame=''>1.12769 0.073786 1.44578 -1.57003 0.000206 -0.261799</pose>
      <inertial>
        <pose frame=''>0.0065 0 0 0 -0 0</pose>
        <mass>0.01</mass>
        <inertia>
          <ixx>0.001</ixx>
          <ixy>0</ixy>
          <ixz>0</ixz>
          <iyy>0.001</iyy>
          <iyz>0</iyz>
          <izz>0.001</izz>
        </inertia>
      </inertial>
      <collision name='hand_ring_virtual_3_link_collision'>
        <pose frame=''>0 0 0 0 -0 0</pose>
        <geometry>
          <box>
            <size>0.013 0.002 0.012</size>
          </box>
        </geometry>
        <surface>
          <contact>
            <ode/>
          </contact>
          <friction>
            <ode/>
          </friction>
        </surface>
      </collision>
      <visual name='hand_ring_virtual_3_link_visual'>
        <pose frame=''>0.0065 0 0 0 -0 0</pose>
        <geometry>
          <box>
            <size>0.013 0.002 0.012</size>
          </box>
        </geometry>
        <material>
          <script>
            <name>Gazebo/Black</name>
            <uri>file://media/materials/scripts/gazebo.material</uri>
          </script>
        </material>
      </visual>
      <gravity>1</gravity>
      <velocity_decay/>
    </link>
    <joint name='hand_ring_virtual_3_joint' type='revolute'>
      <child>hand_ring_virtual_3_link</child>
      <parent>hand_ring_flex_2_link</parent>
      <axis>
        <xyz>0.258819 0.965926 0.000769</xyz>
        <limit>
          <lower>0</lower>
          <upper>0.785398</upper>
          <effort>2</effort>
          <velocity>2</velocity>
        </limit>
        <dynamics>
          <damping>0.5</damping>
          <friction>0</friction>
          <spring_reference>0</spring_reference>
          <spring_stiffness>0</spring_stiffness>
        </dynamics>
        <use_parent_model_frame>1</use_parent_model_frame>
      </axis>
    </joint>
    <link name='hand_ring_flex_3_link'>
      <pose frame=''>1.14025 0.070421 1.44578 -1.57003 0.000206 -0.261799</pose>
      <inertial>
        <pose frame=''>0.0096 0.003 0 0 -0 0</pose>
        <mass>0.015</mass>
        <inertia>
          <ixx>0.001</ixx>
          <ixy>0</ixy>
          <ixz>0</ixz>
          <iyy>0.001</iyy>
          <iyz>0</iyz>
          <izz>0.001</izz>
        </inertia>
      </inertial>
      <collision name='hand_ring_flex_3_link_collision'>
        <pose frame=''>0 0 0 0 -0 0</pose>
        <geometry>
          <mesh>
            <scale>1 1 1</scale>
            <uri>model://hey5_description/meshes/finger_flex_tip_collision.stl</uri>
          </mesh>
        </geometry>
        <surface>
          <contact>
            <ode/>
          </contact>
          <friction>
            <ode/>
          </friction>
        </surface>
      </collision>
      <visual name='hand_ring_flex_3_link_visual'>
        <pose frame=''>0 0 0 0 -0 0</pose>
        <geometry>
          <mesh>
            <scale>1 1 1</scale>
            <uri>model://hey5_description/meshes/finger_flex_tip_collision.stl</uri>
          </mesh>
        </geometry>
        <material>
          <script>
            <name>Gazebo/Black</name>
            <uri>file://media/materials/scripts/gazebo.material</uri>
          </script>
        </material>
      </visual>
      <gravity>1</gravity>
      <velocity_decay/>
    </link>
    <joint name='hand_ring_flex_3_joint' type='revolute'>
      <child>hand_ring_flex_3_link</child>
      <parent>hand_ring_virtual_3_link</parent>
      <axis>
        <xyz>0.258819 0.965926 0.000769</xyz>
        <limit>
          <lower>0</lower>
          <upper>0.785398</upper>
          <effort>2</effort>
          <velocity>2</velocity>
        </limit>
        <dynamics>
          <damping>0.5</damping>
          <friction>0</friction>
          <spring_reference>0</spring_reference>
          <spring_stiffness>0</spring_stiffness>
        </dynamics>
        <use_parent_model_frame>1</use_parent_model_frame>
      </axis>
    </joint>
    <link name='hand_thumb_abd_link'>
      <pose frame=''>1.0401 0.138011 1.43663 -1.57046 -0.000722 1.13446</pose>
      <inertial>
        <pose frame=''>-0.0132 0.0037 -0.0017 0 -0 0</pose>
        <mass>0.014</mass>
        <inertia>
          <ixx>0.001</ixx>
          <ixy>0</ixy>
          <ixz>0</ixz>
          <iyy>0.001</iyy>
          <iyz>0</iyz>
          <izz>0.001</izz>
        </inertia>
      </inertial>
      <collision name='hand_thumb_abd_link_collision'>
        <pose frame=''>0 0 0 0 -0 0</pose>
        <geometry>
          <mesh>
            <scale>1 1 1</scale>
            <uri>model://hey5_description/meshes/thumb_abd_collision.stl</uri>
          </mesh>
        </geometry>
        <surface>
          <contact>
            <ode/>
          </contact>
          <friction>
            <ode/>
          </friction>
        </surface>
      </collision>
      <visual name='hand_thumb_abd_link_visual'>
        <pose frame=''>0 0 0 0 -0 0</pose>
        <geometry>
          <mesh>
            <scale>1 1 1</scale>
            <uri>model://hey5_description/meshes/thumb_abd_collision.stl</uri>
          </mesh>
        </geometry>
        <material>
          <script>
            <name>Gazebo/Black</name>
            <uri>file://media/materials/scripts/gazebo.material</uri>
          </script>
        </material>
      </visual>
      <gravity>1</gravity>
      <velocity_decay/>
    </link>
    <joint name='hand_thumb_abd_joint' type='revolute'>
      <child>hand_thumb_abd_link</child>
      <parent>fore_link</parent>
      <axis>
        <xyz>-0.906308 0.422618 0.000337</xyz>
        <limit>
          <lower>0</lower>
          <upper>1.5708</upper>
          <effort>2</effort>
          <velocity>2</velocity>
        </limit>
        <dynamics>
          <damping>0.5</damping>
          <friction>0</friction>
          <spring_reference>0</spring_reference>
          <spring_stiffness>0</spring_stiffness>
        </dynamics>
        <use_parent_model_frame>1</use_parent_model_frame>
      </axis>
    </joint>
    <link name='hand_thumb_virtual_1_link'>
      <pose frame=''>1.04961 0.158405 1.43365 -2.7147 -0.000722 1.13446</pose>
      <inertial>
        <pose frame=''>0.0065 0 0 0 -0 0</pose>
        <mass>0.01</mass>
        <inertia>
          <ixx>0.001</ixx>
          <ixy>0</ixy>
          <ixz>0</ixz>
          <iyy>0.001</iyy>
          <iyz>0</iyz>
          <izz>0.001</izz>
        </inertia>
      </inertial>
      <collision name='hand_thumb_virtual_1_link_collision'>
        <pose frame=''>0 0 0 0 -0 0</pose>
        <geometry>
          <box>
            <size>0.013 0.002 0.012</size>
          </box>
        </geometry>
        <surface>
          <contact>
            <ode/>
          </contact>
          <friction>
            <ode/>
          </friction>
        </surface>
      </collision>
      <visual name='hand_thumb_virtual_1_link_visual'>
        <pose frame=''>0.0065 0 0 0 -0 0</pose>
        <geometry>
          <box>
            <size>0.013 0.002 0.012</size>
          </box>
        </geometry>
        <material>
          <script>
            <name>Gazebo/Black</name>
            <uri>file://media/materials/scripts/gazebo.material</uri>
          </script>
        </material>
      </visual>
      <gravity>1</gravity>
      <velocity_decay/>
    </link>
    <joint name='hand_thumb_virtual_1_joint' type='revolute'>
      <child>hand_thumb_virtual_1_link</child>
      <parent>hand_thumb_abd_link</parent>
      <axis>
        <xyz>-0.374976 0.175579 -0.910256</xyz>
        <limit>
          <lower>0</lower>
          <upper>0.785398</upper>
          <effort>2</effort>
          <velocity>2</velocity>
        </limit>
        <dynamics>
          <damping>0.5</damping>
          <friction>0</friction>
          <spring_reference>0</spring_reference>
          <spring_stiffness>0</spring_stiffness>
        </dynamics>
        <use_parent_model_frame>1</use_parent_model_frame>
      </axis>
    </joint>
    <link name='hand_thumb_flex_1_link'>
      <pose frame=''>1.0551 0.170187 1.43366 -2.7147 -0.000722 1.13446</pose>
      <inertial>
        <pose frame=''>0.0047 0.0031 0 0 -0 0</pose>
        <mass>0.009</mass>
        <inertia>
          <ixx>0.001</ixx>
          <ixy>0</ixy>
          <ixz>0</ixz>
          <iyy>0.001</iyy>
          <iyz>0</iyz>
          <izz>0.001</izz>
        </inertia>
      </inertial>
      <collision name='hand_thumb_flex_1_link_collision'>
        <pose frame=''>0 0 0 0 -0 0</pose>
        <geometry>
          <mesh>
            <scale>1 1 1</scale>
            <uri>model://hey5_description/meshes/finger_flex_collision.stl</uri>
          </mesh>
        </geometry>
        <surface>
          <contact>
            <ode/>
          </contact>
          <friction>
            <ode/>
          </friction>
        </surface>
      </collision>
      <visual name='hand_thumb_flex_1_link_visual'>
        <pose frame=''>0 0 0 0 -0 0</pose>
        <geometry>
          <mesh>
            <scale>1 1 1</scale>
            <uri>model://hey5_description/meshes/finger_flex_collision.stl</uri>
          </mesh>
        </geometry>
        <material>
          <script>
            <name>Gazebo/Black</name>
            <uri>file://media/materials/scripts/gazebo.material</uri>
          </script>
        </material>
      </visual>
      <gravity>1</gravity>
      <velocity_decay/>
    </link>
    <joint name='hand_thumb_flex_1_joint' type='revolute'>
      <child>hand_thumb_flex_1_link</child>
      <parent>hand_thumb_virtual_1_link</parent>
      <axis>
        <xyz>-0.374976 0.175579 -0.910256</xyz>
        <limit>
          <lower>0</lower>
          <upper>0.785398</upper>
          <effort>2</effort>
          <velocity>2</velocity>
        </limit>
        <dynamics>
          <damping>0.5</damping>
          <friction>0</friction>
          <spring_reference>0</spring_reference>
          <spring_stiffness>0</spring_stiffness>
        </dynamics>
        <use_parent_model_frame>1</use_parent_model_frame>
      </axis>
    </joint>
    <link name='hand_thumb_virtual_2_link'>
      <pose frame=''>1.05891 0.178344 1.43366 -2.7147 -0.000722 1.13446</pose>
      <inertial>
        <pose frame=''>0.0065 0 0 0 -0 0</pose>
        <mass>0.01</mass>
        <inertia>
          <ixx>0.001</ixx>
          <ixy>0</ixy>
          <ixz>0</ixz>
          <iyy>0.001</iyy>
          <iyz>0</iyz>
          <izz>0.001</izz>
        </inertia>
      </inertial>
      <collision name='hand_thumb_virtual_2_link_collision'>
        <pose frame=''>0 0 0 0 -0 0</pose>
        <geometry>
          <box>
            <size>0.013 0.002 0.012</size>
          </box>
        </geometry>
        <surface>
          <contact>
            <ode/>
          </contact>
          <friction>
            <ode/>
          </friction>
        </surface>
      </collision>
      <visual name='hand_thumb_virtual_2_link_visual'>
        <pose frame=''>0.0065 0 0 0 -0 0</pose>
        <geometry>
          <box>
            <size>0.013 0.002 0.012</size>
          </box>
        </geometry>
        <material>
          <script>
            <name>Gazebo/Black</name>
            <uri>file://media/materials/scripts/gazebo.material</uri>
          </script>
        </material>
      </visual>
      <gravity>1</gravity>
      <velocity_decay/>
    </link>
    <joint name='hand_thumb_virtual_2_joint' type='revolute'>
      <child>hand_thumb_virtual_2_link</child>
      <parent>hand_thumb_flex_1_link</parent>
      <axis>
        <xyz>-0.374976 0.175579 -0.910256</xyz>
        <limit>
          <lower>0</lower>
          <upper>0.785398</upper>
          <effort>2</effort>
          <velocity>2</velocity>
        </limit>
        <dynamics>
          <damping>0.5</damping>
          <friction>0</friction>
          <spring_reference>0</spring_reference>
          <spring_stiffness>0</spring_stiffness>
        </dynamics>
        <use_parent_model_frame>1</use_parent_model_frame>
      </axis>
    </joint>
    <link name='hand_thumb_flex_2_link'>
      <pose frame=''>1.0644 0.190126 1.43367 -2.7147 -0.000722 1.13446</pose>
      <inertial>
        <pose frame=''>0.0096 0.003 0 0 -0 0</pose>
        <mass>0.015</mass>
        <inertia>
          <ixx>0.001</ixx>
          <ixy>0</ixy>
          <ixz>0</ixz>
          <iyy>0.001</iyy>
          <iyz>0</iyz>
          <izz>0.001</izz>
        </inertia>
      </inertial>
      <collision name='hand_thumb_flex_2_link_collision'>
        <pose frame=''>0 0 0 0 -0 0</pose>
        <geometry>
          <mesh>
            <scale>1 1 1</scale>
            <uri>model://hey5_description/meshes/finger_flex_tip_collision.stl</uri>
          </mesh>
        </geometry>
        <surface>
          <contact>
            <ode/>
          </contact>
          <friction>
            <ode/>
          </friction>
        </surface>
      </collision>
      <visual name='hand_thumb_flex_2_link_visual'>
        <pose frame=''>0 0 0 0 -0 0</pose>
        <geometry>
          <mesh>
            <scale>1 1 1</scale>
            <uri>model://hey5_description/meshes/finger_flex_tip_collision.stl</uri>
          </mesh>
        </geometry>
        <material>
          <script>
            <name>Gazebo/Black</name>
            <uri>file://media/materials/scripts/gazebo.material</uri>
          </script>
        </material>
      </visual>
      <gravity>1</gravity>
      <velocity_decay/>
    </link>
    <joint name='hand_thumb_flex_2_joint' type='revolute'>
      <child>hand_thumb_flex_2_link</child>
      <parent>hand_thumb_virtual_2_link</parent>
      <axis>
        <xyz>-0.374976 0.175579 -0.910256</xyz>
        <limit>
          <lower>0</lower>
          <upper>0.785398</upper>
          <effort>2</effort>
          <velocity>2</velocity>
        </limit>
        <dynamics>
          <damping>0.5</damping>
          <friction>0</friction>
          <spring_reference>0</spring_reference>
          <spring_stiffness>0</spring_stiffness>
        </dynamics>
        <use_parent_model_frame>1</use_parent_model_frame>
      </axis>
    </joint>
    <link name='hand_thumb_link'>
      <pose frame=''>0.95 0.1 1.45 -1.57 0 0</pose>
      <inertial>
        <pose frame=''>0 0 0 0 -0 0</pose>
        <mass>0.05</mass>
        <inertia>
          <ixx>0.001</ixx>
          <ixy>0</ixy>
          <ixz>0</ixz>
          <iyy>0.001</iyy>
          <iyz>0</iyz>
          <izz>0.001</izz>
        </inertia>
      </inertial>
      <collision name='hand_thumb_link_collision'>
        <pose frame=''>0 0 0 0 -0 0</pose>
        <geometry>
          <sphere>
            <radius>0.001</radius>
          </sphere>
        </geometry>
      </collision>
      <visual name='hand_thumb_link_visual'>
        <pose frame=''>0 0 0 0 -0 0</pose>
        <geometry>
          <sphere>
            <radius>0.001</radius>
          </sphere>
        </geometry>
      </visual>
    </link>
    <joint name='hand_thumb_joint' type='revolute'>
      <child>hand_thumb_link</child>
      <parent>fore_link</parent>
      <axis>
        <xyz>0 1 0.000796</xyz>
        <limit>
          <lower>-2.61799</lower>
          <upper>6.28319</upper>
          <effort>2</effort>
          <velocity>3.35</velocity>
        </limit>
        <dynamics>
          <damping>0.5</damping>
          <friction>0</friction>
          <spring_reference>0</spring_reference>
          <spring_stiffness>0</spring_stiffness>
        </dynamics>
        <use_parent_model_frame>1</use_parent_model_frame>
      </axis>
    </joint>
    <plugin name='gazebo_ros_control' filename='libgazebo_ros_control.so'>
      <robotNamespace>/arm_stand</robotNamespace>
      <robotSimType>gazebo_ros_control/DefaultRobotHWSim</robotSimType>
    </plugin>
    <static>0</static>
    <plugin name='gazebo_hand_thumb' filename='libgazebo_underactuated_finger.so'>
      <actuatedJoint>hand_thumb_joint</actuatedJoint>
      <virtualJoint>
        <name>hand_thumb_abd_joint</name>
        <scale_factor>2.0</scale_factor>
      </virtualJoint>
      <virtualJoint>
        <name>hand_thumb_flex_1_joint</name>
        <scale_factor>2.5</scale_factor>
      </virtualJoint>
      <virtualJoint>
        <name>hand_thumb_virtual_1_joint</name>
        <scale_factor>3.0</scale_factor>
      </virtualJoint>
      <virtualJoint>
        <name>hand_thumb_flex_2_joint</name>
        <scale_factor>3.5</scale_factor>
      </virtualJoint>
      <virtualJoint>
        <name>hand_thumb_virtual_2_joint</name>
        <scale_factor>3.0</scale_factor>
      </virtualJoint>
    </plugin>
    <plugin name='gazebo_hand_index' filename='libgazebo_underactuated_finger.so'>
      <actuatedJoint>hand_index_joint</actuatedJoint>
      <virtualJoint>
        <name>hand_index_abd_joint</name>
        <scale_factor>5.0</scale_factor>
      </virtualJoint>
      <virtualJoint>
        <name>hand_index_flex_1_joint</name>
        <scale_factor>2.5</scale_factor>
      </virtualJoint>
      <virtualJoint>
        <name>hand_index_virtual_1_joint</name>
        <scale_factor>3.0</scale_factor>
      </virtualJoint>
      <virtualJoint>
        <name>hand_index_flex_2_joint</name>
        <scale_factor>3.5</scale_factor>
      </virtualJoint>
      <virtualJoint>
        <name>hand_index_virtual_2_joint</name>
        <scale_factor>3.5</scale_factor>
      </virtualJoint>
      <virtualJoint>
        <name>hand_index_flex_3_joint</name>
        <scale_factor>4.0</scale_factor>
      </virtualJoint>
    </plugin>
    <plugin name='gazebo_hand_middle' filename='libgazebo_underactuated_finger.so'>
      <actuatedJoint>hand_mrl_joint</actuatedJoint>
      <virtualJoint>
        <name>hand_middle_flex_1_joint</name>
        <scale_factor>2.5</scale_factor>
      </virtualJoint>
      <virtualJoint>
        <name>hand_middle_virtual_1_joint</name>
        <scale_factor>3.0</scale_factor>
      </virtualJoint>
      <virtualJoint>
        <name>hand_middle_flex_2_joint</name>
        <scale_factor>3.5</scale_factor>
      </virtualJoint>
      <virtualJoint>
        <name>hand_middle_virtual_2_joint</name>
        <scale_factor>3.5</scale_factor>
      </virtualJoint>
      <virtualJoint>
        <name>hand_middle_flex_3_joint</name>
        <scale_factor>4.0</scale_factor>
      </virtualJoint>
    </plugin>
    <plugin name='gazebo_hand_ring' filename='libgazebo_underactuated_finger.so'>
      <actuatedJoint>hand_mrl_joint</actuatedJoint>
      <virtualJoint>
        <name>hand_ring_flex_1_joint</name>
        <scale_factor>2.5</scale_factor>
      </virtualJoint>
      <virtualJoint>
        <name>hand_ring_virtual_1_joint</name>
        <scale_factor>3.0</scale_factor>
      </virtualJoint>
      <virtualJoint>
        <name>hand_ring_flex_2_joint</name>
        <scale_factor>3.5</scale_factor>
      </virtualJoint>
      <virtualJoint>
        <name>hand_ring_virtual_2_joint</name>
        <scale_factor>3.5</scale_factor>
      </virtualJoint>
      <virtualJoint>
        <name>hand_ring_flex_3_joint</name>
        <scale_factor>4.0</scale_factor>
      </virtualJoint>
    </plugin>
    <plugin name='gazebo_hand_little' filename='libgazebo_underactuated_finger.so'>
      <actuatedJoint>hand_mrl_joint</actuatedJoint>
      <virtualJoint>
        <name>hand_little_flex_1_joint</name>
        <scale_factor>2.5</scale_factor>
      </virtualJoint>
      <virtualJoint>
        <name>hand_little_virtual_1_joint</name>
        <scale_factor>3.0</scale_factor>
      </virtualJoint>
      <virtualJoint>
        <name>hand_little_flex_2_joint</name>
        <scale_factor>3.5</scale_factor>
      </virtualJoint>
      <virtualJoint>
        <name>hand_little_virtual_2_joint</name>
        <scale_factor>3.5</scale_factor>
      </virtualJoint>
      <virtualJoint>
        <name>hand_little_flex_3_joint</name>
        <scale_factor>4.0</scale_factor>
      </virtualJoint>
    </plugin>
  </model>
</sdf>
